Workbook

Sheet Leeme
A1: Detección de robots y cálculo de v y ω — hoja de cálculo explicativa
A2: Ensayo 20262409_1600_22QR_60 · robot 3 · cuadro 6034 (t = 2011,33 s real). Todo se calcula con fórmulas a partir de los píxeles del video.
B4: Qué es | C4: Reproduce, con fórmulas de Excel, lo que hace VidFetch para (1) encontrar los círculos de los robots en un cuadro, (2) calcular el vector velocidad y (3) calcular el giro θ y la velocidad angular ω. Nada más.
B5: Recorrido | C5: Imagen gris → reducción ×0,511 → filtro de anillo R(x,y) → mancha de R (trackpy) → validación por cobertura del anillo oscuro → centro (x, y) en cada cuadro → Savitzky–Golay → v = (vx, vy), |v|, φ. En paralelo: firma polar alrededor del centro → correlación entre cuadros → Δθ → θ acumulado → Savitzky–Golay → ω.
B7: Hojas
B8: Parametros | C8: Constantes de la sesión (radios, escala, umbrales, diámetro real, cuadros por segundo). Celdas azules = datos; el resto se deriva.
B9: Img_analisis | C9: Recorte de la imagen gris ya reducida ×0,511 (píxeles de análisis). Cada celda es un píxel (0 = negro, 255 = blanco).
B10: Filtro_anillo | C10: Las dos máscaras (disco claro y anillo oscuro) y el cálculo de R en UN centro editable: μ_disco, μ_anillo, compuerta y R.
B11: Mapa_R | C11: El mismo cálculo de R para cada píxel de una zona (robot 3 y un hueco entre robots) y el centro de la mancha, refinado como hace trackpy.
B12: Img_completa | C12: Recorte a resolución completa del cuadro 6034 (para la cobertura y la firma polar).
B13: Cobertura | C13: 360 rayos desde el centro; un rayo cuenta si su píxel más oscuro dentro del anillo es < 68. Robot real ≈ 0,86; hueco ≈ 0,67 (rechazado, umbral 0,82).
B14: Img_6035 | C14: Recorte del cuadro siguiente (6035), para medir el giro entre los dos cuadros.
B15: Firma_6034 / Firma_6035 | C15: Muestreo polar 128 ángulos × radios, perfil angular por banda (batería y anillo de la placa) y sus 12 primeros armónicos de Fourier.
B16: Giro | C16: Correlación circular c(Δ) entre las dos firmas, ángulo Δ* del máximo, calidad q y conversión a sentido real (video espejado).
B17: Velocidad | C17: Trayectoria del robot 3 (95 cuadros), derivada Savitzky–Golay de 5 puntos → vx, vy, |v|, φ; comparada con la app y con diferencias finitas.
B18: Rotacion | C18: θ acumulado (de la app) y ω por la misma fórmula de Savitzky–Golay; comparación con la app.
B20: Colores | C20: Texto azul sobre amarillo = dato o celda editable. Verde = resultado principal. Grises = imagen (escala 0–255).
... B23: Fuente | C23: software/vidfetch/core/detection.py (robot_response, ring_coverage, locate), rotation.py (signatures, rel_angle, solve_angles), kinematics.py (_derivative). Explicación con figuras: documento «Detección de robots y cálculo de velocidad y velocidad angular».

Sheet Parametros
A1: Parámetros de la sesión
A2: Valores guardados en VA_20262409_1600_22QR_60_analisis.npz. Azul = dato; negro = derivado.
A3: Nombre | B3: Valor | C3: Unidad | D3: Qué es
A4: r_int | B4: 35.2 | C4: px | D4: Radio del disco claro (placa del robot), resolución completa
A5: r_ext | B5: 47 | C5: px | D5: Radio exterior del anillo oscuro (borde del robot)
A6: escala | B6: 0.511 | C6: — | D6: Factor de reducción para el análisis (más rápido; el robot queda con radio ≈ 24 px)
A7: r_int_a | B7: =r_int*escala -> 17.9872 | C7: px | D7: r_int en píxeles de análisis
A8: r_ext_a | B8: =r_ext*escala -> 24.017 | C8: px | D8: r_ext en píxeles de análisis; la máscara es de 2·⌈r_ext_a⌉+1 = 51 px de lado
A9: Gmax | B9: 106 | C9: nivel | D9: Compuerta: si el anillo es más claro que esto, R se anula (evita falsos positivos en zonas claras)
A10: oscuro | B10: 68 | C10: nivel | D10: Un píxel del anillo cuenta como oscuro si su gris es menor que esto
A11: cob_min | B11: 0.82 | C11: — | D11: Fracción mínima de rayos con anillo oscuro para aceptar un candidato
A12: margen | B12: =MAX(0.5,0.17*(r_ext-r_int)) -> 2.006 | C12: px | D12: Margen para no tocar los bordes del anillo
A13: r0_cob | B13: =r_int+margen -> 37.206 | C13: px | D13: Radio interior de la banda de cobertura
A14: r1_cob | B14: =MAX(r0_cob+1,r_ext-margen) -> 44.994 | C14: px | D14: Radio exterior de la banda de cobertura
A15: r0_i | B15: =INT(r0_cob) -> 37 | C15: px | D15: Primer radio entero muestreado (piso de r0)
A16: r1_i | B16: =ROUNDUP(r1_cob,0) -> 45 | C16: px | D16: Techo de r1; se muestrean los radios r0_i … r1_i − 1
A17: diam_tp | B17: =ROUND(1.4*r_int*escala,0)+1-MOD(ROUND(1.4*r_int*escala,0),2) -> 25 | C17: px | D17: Diámetro de trackpy en el mapa R: 1,4·r_int·escala redondeado al impar (OR binario con 1)
A18: rad_tp | B18: =INT(diam_tp/2) -> 12 | C18: px | D18: Radio de la máscara de trackpy para el centroide
A19: D_mm | B19: 35 | C19: mm | D19: Diámetro real del robot (calibración espacial)
A20: s_mm | B20: =D_mm/(2*r_ext) -> 0.37234043 | C20: mm/px | D20: Escala espacial: s = D / (2·r_ext)
A21: f_r | B21: 3 | C21: cuadros/s | D21: Cuadros por segundo REAL del time-lapse (3 cuadros = 1 s)
A22: dt | B22: =1/f_r -> 0.33333333 | C22: s | D22: Paso temporal entre cuadros, Δt = 1/f_r
A23: w_sg | B23: 5 | C23: cuadros | D23: Ventana Savitzky–Golay (orden 2). Las fórmulas de las hojas están escritas para w = 5
A24: n_ang | B24: 128 | C24: — | D24: Ángulos de la firma polar (2,81° por muestra)
A25: K_arm | B25: 12 | C25: — | D25: Armónicos de Fourier que se guardan por banda
A26: b1_c0 | B26: =INT(0.15*r_ext) -> 7 | C26: px | D26: Banda 1 (batería, chapa, puntos): radios b1_c0 … b1_c1 − 1
A27: b1_c1 | B27: =INT(0.7*r_ext) -> 32 | C27: px
A28: b2_c0 | B28: =INT(0.75*r_ext) -> 35 | C28: px | D28: Banda 2 (anillo de la placa: separadores, componentes): radios b2_c0 … b2_c1 − 1
A29: b2_c1 | B29: =INT(0.95*r_ext) -> 44 | C29: px

Sheet Img_analisis
A1: Imagen gris reducida ×0,511 (cv2.resize, INTER_AREA) — cuadro 6034, zona del robot 3 y su vecino
A2: x0 | B2: 141 | D2: y0 | E2: 45 | G2: Fila 3 = x (px), columna B = y (px). Valor = nivel de gris 0–255.
C3: 141 | D3: 142 | E3: 143 | F3: 144 | G3: 145 | H3: 146 | I3: 147 | J3: 148 | K3: 149 | L3: 150 | M3: 151 | N3: 152 | O3: 153 | P3: 154 | Q3: 155 | R3: 156 | S3: 157 | T3: 158 | U3: 159 | V3: 160 | W3: 161 | X3: 162 | Y3: 163 | Z3: 164 | AA3: 165 | AB3: 166 | AC3: 167 | AD3: 168 | AE3: 169 | AF3: 170 | AG3: 171 | AH3: 172 | AI3: 173 | AJ3: 174 | AK3: 175 | AL3: 176 | AM3: 177 | AN3: 178 | AO3: 179 | AP3: 180 | AQ3: 181 | AR3: 182 | AS3: 183 | AT3: 184 | AU3: 185 | AV3: 186 | AW3: 187 | AX3: 188 | AY3: 189 | AZ3: 190 | BA3: 191 | BB3: 192 | BC3: 193 | BD3: 194 | BE3: 195 | BF3: 196 | BG3: 197 | BH3: 198 | BI3: 199 | BJ3: 200 | BK3: 201 | BL3: 202 | BM3: 203 | BN3: 204 | BO3: 205 | BP3: 206 | BQ3: 207 | BR3: 208 | BS3: 209 | BT3: 210 | BU3: 211 | BV3: 212 | BW3: 213 | BX3: 214 | BY3: 215 | BZ3: 216 | CA3: 217 | CB3: 218 | CC3: 219 | CD3: 220 | CE3: 221 | CF3: 222 | CG3: 223 | CH3: 224 | CI3: 225 | CJ3: 226 | CK3: 227 | CL3: 228 | CM3: 229 | CN3: 230 | CO3: 231 | CP3: 232 | CQ3: 233 | CR3: 234 | CS3: 235 | CT3: 236 | CU3: 237 | CV3: 238 | CW3: 239 | CX3: 240 | CY3: 241 | CZ3: 242 | DA3: 243 | DB3: 244 | DC3: 245 | DD3: 246 | DE3: 247 | DF3: 248 | DG3: 249 | DH3: 250 | DI3: 251 | DJ3: 252 | DK3: 253 | DL3: 254
B4: 45 | C4: 100 | D4: 39 | E4: 7 | F4: 26 | G4: 43 | H4: 21 | I4: 12 | J4: 42 | K4: 40 | L4: 82 | M4: 68 | N4: 111 | O4: 174 | P4: 146 | Q4: 182 | R4: 204 | S4: 202 | T4: 192 | U4: 189 | V4: 204 | W4: 199 | X4: 212 | Y4: 191 | Z4: 209 | AA4: 188 | AB4: 198 | AC4: 212 | AD4: 213 | AE4: 218 | AF4: 209 | AG4: 217 | AH4: 197 | AI4: 238 | AJ4: 174 | AK4: 86 | AL4: 122 | AM4: 43 | AN4: 22 | AO4: 33 | AP4: 20 | AQ4: 17 | AR4: 32 | AS4: 40 | AT4: 67 | AU4: 212 | AV4: 240 | AW4: 225 | AX4: 78 | AY4: 46 | AZ4: 124 | BA4: 221 | BB4: 229 | BC4: 229 | BD4: 131 | BE4: 47 | BF4: 49 | BG4: 16 | BH4: 96 | BI4: 154 | BJ4: 128 | BK4: 177 | BL4: 233 | BM4: 230 | BN4: 207 | BO4: 182 | BP4: 170 | BQ4: 156 | BR4: 165 | BS4: 133 | BT4: 94 | BU4: 152 | BV4: 143 | BW4: 77 | BX4: 56 | BY4: 59 | BZ4: 94 | CA4: 102 | CB4: 94 | CC4: 193 | CD4: 204 | CE4: 244 | CF4: 254 | CG4: 253 | CH4: 251 | CI4: 251 | CJ4: 249 | CK4: 247 | CL4: 245 | CM4: 243 | CN4: 238 | CO4: 231 | CP4: 238 | CQ4: 188 | CR4: 125 | CS4: 137 | CT4: 69 | CU4: 34 | CV4: 42 | CW4: 34 | CX4: 47 | CY4: 90 | CZ4: 87 | DA4: 85 | DB4: 85 | DC4: 88 | DD4: 78 | DE4: 62 | DF4: 34 | DG4: 33 | DH4: 69 | DI4: 65 | DJ4: 55 | DK4: 49 | DL4: 49
B5: 46 | C5: 77 | D5: 67 | E5: 13 | F5: 18 | G5: 39 | H5: 38 | I5: 16 | J5: 11 | K5: 25 | L5: 30 | M5: 80 | N5: 76 | O5: 93 | P5: 168 | Q5: 136 | R5: 133 | S5: 176 | T5: 193 | U5: 197 | V5: 197 | W5: 186 | X5: 201 | Y5: 203 | Z5: 201 | AA5: 197 | AB5: 189 | AC5: 204 | AD5: 176 | AE5: 196 | AF5: 174 | AG5: 171 | AH5: 226 | AI5: 142 | AJ5: 86 | AK5: 112 | AL5: 50 | AM5: 19 | AN5: 29 | AO5: 33 | AP5: 25 | AQ5: 36 | AR5: 30 | AS5: 37 | AT5: 36 | AU5: 151 | AV5: 198 | AW5: 140 | AX5: 57 | AY5: 47 | AZ5: 85 | BA5: 124 | BB5: 106 | BC5: 102 | BD5: 78 | BE5: 45 | BF5: 46 | BG5: 14 | BH5: 94 | BI5: 156 | BJ5: 130 | BK5: 176 | BL5: 232 | BM5: 228 | BN5: 213 | BO5: 181 | BP5: 163 | BQ5: 171 | BR5: 180 | BS5: 226 | BT5: 222 | BU5: 141 | BV5: 131 | BW5: 56 | BX5: 55 | BY5: 56 | BZ5: 77 | CA5: 82 | CB5: 90 | CC5: 89 | CD5: 55 | CE5: 114 | CF5: 237 | CG5: 252 | CH5: 252 | CI5: 250 | CJ5: 250 | CK5: 247 | CL5: 249 | CM5: 246 | CN5: 244 | CO5: 233 | CP5: 231 | CQ5: 205 | CR5: 122 | CS5: 134 | CT5: 72 | CU5: 34 | CV5: 41 | CW5: 40 | CX5: 54 | CY5: 90 | CZ5: 87 | DA5: 87 | DB5: 87 | DC5: 87 | DD5: 86 | DE5: 77 | DF5: 57 | DG5: 45 | DH5: 34 | DI5: 55 | DJ5: 57 | DK5: 51 | DL5: 52
B6: 47 | C6: 99 | D6: 100 | E6: 42 | F6: 13 | G6: 23 | H6: 37 | I6: 35 | J6: 17 | K6: 9 | L6: 12 | M6: 26 | N6: 71 | O6: 98 | P6: 65 | Q6: 123 | R6: 165 | S6: 136 | T6: 133 | U6: 174 | V6: 183 | W6: 165 | X6: 183 | Y6: 211 | Z6: 217 | AA6: 203 | AB6: 193 | AC6: 197 | AD6: 164 | AE6: 175 | AF6: 221 | AG6: 182 | AH6: 97 | AI6: 96 | AJ6: 100 | AK6: 41 | AL6: 16 | AM6: 35 | AN6: 48 | AO6: 21 | AP6: 24 | AQ6: 29 | AR6: 23 | AS6: 28 | AT6: 38 | AU6: 34 | AV6: 65 | AW6: 40 | AX6: 42 | AY6: 42 | AZ6: 76 | BA6: 201 | BB6: 195 | BC6: 201 | BD6: 122 | BE6: 48 | BF6: 46 | BG6: 14 | BH6: 82 | BI6: 155 | BJ6: 133 | BK6: 156 | BL6: 226 | BM6: 227 | BN6: 206 | BO6: 179 | BP6: 170 | BQ6: 161 | BR6: 118 | BS6: 123 | BT6: 191 | BU6: 150 | BV6: 126 | BW6: 73 | BX6: 53 | BY6: 47 | BZ6: 60 | CA6: 72 | CB6: 57 | CC6: 38 | CD6: 33 | CE6: 72 | CF6: 136 | CG6: 227 | CH6: 254 | CI6: 250 | CJ6: 248 | CK6: 247 | CL6: 248 | CM6: 248 | CN6: 239 | CO6: 227 | CP6: 241 | CQ6: 181 | CR6: 122 | CS6: 137 | CT6: 65 | CU6: 39 | CV6: 39 | CW6: 30 | CX6: 43 | CY6: 92 | CZ6: 87 | DA6: 86 | DB6: 86 | DC6: 85 | DD6: 87 | DE6: 84 | DF6: 79 | DG6: 67 | DH6: 55 | DI6: 29 | DJ6: 43 | DK6: 57 | DL6: 52
B7: 48 | C7: 81 | D7: 94 | E7: 75 | F7: 26 | G7: 12 | H7: 29 | I7: 37 | J7: 34 | K7: 15 | L7: 5 | M7: 10 | N7: 22 | O7: 55 | P7: 100 | Q7: 94 | R7: 78 | S7: 127 | T7: 175 | U7: 159 | V7: 146 | W7: 152 | X7: 161 | Y7: 154 | Z7: 153 | AA7: 148 | AB7: 162 | AC7: 189 | AD7: 199 | AE7: 160 | AF7: 97 | AG7: 89 | AH7: 108 | AI7: 67 | AJ7: 32 | AK7: 12 | AL7: 31 | AM7: 51 | AN7: 30 | AO7: 121 | AP7: 95 | AQ7: 35 | AR7: 21 | AS7: 20 | AT7: 27 | AU7: 42 | AV7: 52 | AW7: 46 | AX7: 46 | AY7: 39 | AZ7: 41 | BA7: 112 | BB7: 106 | BC7: 108 | BD7: 61 | BE7: 47 | BF7: 51 | BG7: 15 | BH7: 62 | BI7: 154 | BJ7: 136 | BK7: 149 | BL7: 232 | BM7: 228 | BN7: 212 | BO7: 183 | BP7: 179 | BQ7: 172 | BR7: 116 | BS7: 117 | BT7: 131 | BU7: 141 | BV7: 145 | BW7: 129 | BX7: 123 | BY7: 141 | BZ7: 168 | CA7: 145 | CB7: 66 | CC7: 26 | CD7: 77 | CE7: 126 | CF7: 110 | CG7: 96 | CH7: 174 | CI7: 244 | CJ7: 250 | CK7: 244 | CL7: 242 | CM7: 244 | CN7: 238 | CO7: 237 | CP7: 235 | CQ7: 193 | CR7: 128 | CS7: 131 | CT7: 54 | CU7: 42 | CV7: 36 | CW7: 54 | CX7: 52 | CY7: 95 | CZ7: 90 | DA7: 88 | DB7: 85 | DC7: 85 | DD7: 89 | DE7: 90 | DF7: 84 | DG7: 79 | DH7: 70 | DI7: 57 | DJ7: 29 | DK7: 36 | DL7: 52
B8: 49 | C8: 80 | D8: 73 | E8: 54 | F8: 18 | G8: 14 | H8: 13 | I8: 18 | J8: 31 | K8: 35 | L8: 24 | M8: 9 | N8: 15 | O8: 17 | P8: 36 | Q8: 66 | R8: 106 | S8: 95 | T8: 71 | U8: 77 | V8: 105 | W8: 116 | X8: 143 | Y8: 149 | Z8: 151 | AA8: 134 | AB8: 121 | AC8: 102 | AD8: 92 | AE8: 98 | AF8: 103 | AG8: 79 | AH8: 42 | AI8: 21 | AJ8: 29 | AK8: 25 | AL8: 19 | AM8: 36 | AN8: 100 | AO8: 226 | AP8: 183 | AQ8: 66 | AR8: 22 | AS8: 22 | AT8: 21 | AU8: 33 | AV8: 40 | AW8: 34 | AX8: 30 | AY8: 22 | AZ8: 34 | BA8: 100 | BB8: 92 | BC8: 82 | BD8: 48 | BE8: 46 | BF8: 46 | BG8: 24 | BH8: 36 | BI8: 143 | BJ8: 140 | BK8: 140 | BL8: 230 | BM8: 236 | BN8: 202 | BO8: 194 | BP8: 184 | BQ8: 173 | BR8: 106 | BS8: 118 | BT8: 136 | BU8: 127 | BV8: 144 | BW8: 134 | BX8: 125 | BY8: 138 | BZ8: 145 | CA8: 198 | CB8: 121 | CC8: 69 | CD8: 132 | CE8: 126 | CF8: 106 | CG8: 73 | CH8: 65 | CI8: 131 | CJ8: 234 | CK8: 245 | CL8: 246 | CM8: 247 | CN8: 239 | CO8: 232 | CP8: 241 | CQ8: 127 | CR8: 134 | CS8: 132 | CT8: 36 | CU8: 42 | CV8: 67 | CW8: 139 | CX8: 71 | CY8: 94 | CZ8: 94 | DA8: 91 | DB8: 88 | DC8: 87 | DD8: 89 | DE8: 93 | DF8: 88 | DG8: 88 | DH8: 82 | DI8: 70 | DJ8: 54 | DK8: 32 | DL8: 34
B9: 50 | C9: 121 | D9: 50 | E9: 35 | F9: 21 | G9: 16 | H9: 16 | I9: 15 | J9: 13 | K9: 31 | L9: 34 | M9: 15 | N9: 7 | O9: 7 | P9: 8 | Q9: 14 | R9: 33 | S9: 55 | T9: 77 | U9: 114 | V9: 96 | W9: 97 | X9: 104 | Y9: 109 | Z9: 112 | AA9: 108 | AB9: 93 | AC9: 109 | AD9: 94 | AE9: 59 | AF9: 33 | AG9: 15 | AH9: 21 | AI9: 54 | AJ9: 35 | AK9: 22 | AL9: 40 | AM9: 179 | AN9: 143 | AO9: 134 | AP9: 232 | AQ9: 152 | AR9: 19 | AS9: 24 | AT9: 39 | AU9: 24 | AV9: 20 | AW9: 21 | AX9: 21 | AY9: 17 | AZ9: 29 | BA9: 65 | BB9: 59 | BC9: 46 | BD9: 29 | BE9: 38 | BF9: 41 | BG9: 32 | BH9: 21 | BI9: 126 | BJ9: 146 | BK9: 130 | BL9: 198 | BM9: 230 | BN9: 216 | BO9: 203 | BP9: 194 | BQ9: 169 | BR9: 106 | BS9: 132 | BT9: 142 | BU9: 124 | BV9: 130 | BW9: 131 | BX9: 142 | BY9: 123 | BZ9: 107 | CA9: 83 | CB9: 43 | CC9: 96 | CD9: 130 | CE9: 109 | CF9: 91 | CG9: 61 | CH9: 66 | CI9: 46 | CJ9: 171 | CK9: 251 | CL9: 246 | CM9: 243 | CN9: 238 | CO9: 245 | CP9: 225 | CQ9: 120 | CR9: 136 | CS9: 111 | CT9: 31 | CU9: 39 | CV9: 66 | CW9: 111 | CX9: 47 | CY9: 103 | CZ9: 96 | DA9: 91 | DB9: 90 | DC9: 88 | DD9: 88 | DE9: 89 | DF9: 87 | DG9: 88 | DH9: 87 | DI9: 79 | DJ9: 69 | DK9: 60 | DL9: 33
B10: 51 | C10: 93 | D10: 42 | E10: 36 | F10: 24 | G10: 16 | H10: 15 | I10: 13 | J10: 8 | K10: 13 | L10: 31 | M10: 32 | N10: 23 | O10: 24 | P10: 29 | Q10: 21 | R10: 5 | S10: 4 | T10: 12 | U10: 26 | V10: 38 | W10: 51 | X10: 61 | Y10: 64 | Z10: 58 | AA10: 52 | AB10: 38 | AC10: 29 | AD10: 14 | AE10: 7 | AF10: 19 | AG10: 36 | AH10: 59 | AI10: 49 | AJ10: 24 | AK10: 30 | AL10: 55 | AM10: 168 | AN10: 217 | AO10: 135 | AP10: 137 | AQ10: 65 | AR10: 31 | AS10: 112 | AT10: 53 | AU10: 14 | AV10: 19 | AW10: 18 | AX10: 16 | AY10: 13 | AZ10: 24 | BA10: 30 | BB10: 37 | BC10: 33 | BD10: 29 | BE10: 35 | BF10: 33 | BG10: 39 | BH10: 16 | BI10: 94 | BJ10: 149 | BK10: 130 | BL10: 163 | BM10: 225 | BN10: 220 | BO10: 212 | BP10: 218 | BQ10: 160 | BR10: 103 | BS10: 137 | BT10: 142 | BU10: 119 | BV10: 136 | BW10: 132 | BX10: 149 | BY10: 136 | BZ10: 140 | CA10: 122 | CB10: 78 | CC10: 95 | CD10: 109 | CE10: 101 | CF10: 78 | CG10: 66 | CH10: 58 | CI10: 105 | CJ10: 237 | CK10: 250 | CL10: 245 | CM10: 241 | CN10: 241 | CO10: 234 | CP10: 201 | CQ10: 122 | CR10: 135 | CS10: 85 | CT10: 36 | CU10: 34 | CV10: 74 | CW10: 97 | CX10: 49 | CY10: 114 | CZ10: 102 | DA10: 95 | DB10: 90 | DC10: 90 | DD10: 89 | DE10: 88 | DF10: 86 | DG10: 86 | DH10: 87 | DI10: 85 | DJ10: 77 | DK10: 69 | DL10: 59
B11: 52 | C11: 61 | D11: 43 | E11: 33 | F11: 20 | G11: 20 | H11: 30 | I11: 39 | J11: 18 | K11: 4 | L11: 11 | M11: 22 | N11: 21 | O11: 18 | P11: 40 | Q11: 52 | R11: 47 | S11: 34 | T11: 23 | U11: 13 | V11: 9 | W11: 5 | X11: 6 | Y11: 5 | Z11: 6 | AA11: 11 | AB11: 14 | AC11: 22 | AD11: 36 | AE11: 49 | AF11: 60 | AG11: 61 | AH11: 39 | AI11: 14 | AJ11: 20 | AK11: 41 | AL11: 51 | AM11: 64 | AN11: 174 | AO11: 157 | AP11: 36 | AQ11: 12 | AR11: 38 | AS11: 52 | AT11: 14 | AU11: 16 | AV11: 18 | AW11: 17 | AX11: 15 | AY11: 11 | AZ11: 24 | BA11: 10 | BB11: 11 | BC11: 13 | BD11: 25 | BE11: 34 | BF11: 25 | BG11: 40 | BH11: 22 | BI11: 47 | BJ11: 149 | BK11: 137 | BL11: 141 | BM11: 219 | BN11: 228 | BO11: 220 | BP11: 232 | BQ11: 132 | BR11: 113 | BS11: 163 | BT11: 175 | BU11: 161 | BV11: 160 | BW11: 160 | BX11: 151 | BY11: 138 | BZ11: 142 | CA11: 193 | CB11: 156 | CC11: 104 | CD11: 96 | CE11: 94 | CF11: 70 | CG11: 61 | CH11: 80 | CI11: 216 | CJ11: 252 | CK11: 247 | CL11: 246 | CM11: 235 | CN11: 241 | CO11: 243 | CP11: 136 | CQ11: 131 | CR11: 126 | CS11: 51 | CT11: 42 | CU11: 43 | CV11: 77 | CW11: 89 | CX11: 55 | CY11: 121 | CZ11: 105 | DA11: 104 | DB11: 97 | DC11: 93 | DD11: 91 | DE11: 88 | DF11: 87 | DG11: 84 | DH11: 84 | DI11: 86 | DJ11: 81 | DK11: 74 | DL11: 67
B12: 53 | C12: 64 | D12: 63 | E12: 39 | F12: 27 | G12: 38 | H12: 90 | I12: 174 | J12: 124 | K12: 12 | L12: 10 | M12: 12 | N12: 15 | O12: 13 | P12: 29 | Q12: 34 | R12: 40 | S12: 46 | T12: 52 | U12: 52 | V12: 51 | W12: 48 | X12: 46 | Y12: 43 | Z12: 48 | AA12: 58 | AB12: 56 | AC12: 62 | AD12: 54 | AE12: 47 | AF12: 31 | AG12: 19 | AH12: 6 | AI12: 18 | AJ12: 32 | AK12: 33 | AL12: 43 | AM12: 45 | AN12: 59 | AO12: 44 | AP12: 30 | AQ12: 18 | AR12: 27 | AS12: 20 | AT12: 20 | AU12: 21 | AV12: 17 | AW12: 15 | AX12: 16 | AY12: 14 | AZ12: 16 | BA12: 5 | BB12: 7 | BC12: 15 | BD12: 28 | BE12: 25 | BF12: 17 | BG12: 35 | BH12: 36 | BI12: 21 | BJ12: 125 | BK12: 150 | BL12: 128 | BM12: 172 | BN12: 230 | BO12: 220 | BP12: 229 | BQ12: 112 | BR12: 114 | BS12: 78 | BT12: 103 | BU12: 121 | BV12: 165 | BW12: 208 | BX12: 163 | BY12: 148 | BZ12: 138 | CA12: 233 | CB12: 236 | CC12: 180 | CD12: 124 | CE12: 90 | CF12: 68 | CG12: 72 | CH12: 185 | CI12: 252 | CJ12: 253 | CK12: 248 | CL12: 243 | CM12: 243 | CN12: 250 | CO12: 189 | CP12: 119 | CQ12: 136 | CR12: 102 | CS12: 38 | CT12: 54 | CU12: 80 | CV12: 110 | CW12: 97 | CX12: 103 | CY12: 149 | CZ12: 131 | DA12: 114 | DB12: 101 | DC12: 90 | DD12: 92 | DE12: 90 | DF12: 90 | DG12: 87 | DH12: 83 | DI12: 83 | DJ12: 84 | DK12: 82 | DL12: 74
B13: 54 | C13: 61 | D13: 58 | E13: 58 | F13: 30 | G13: 87 | H13: 191 | I13: 211 | J13: 183 | K13: 92 | L13: 11 | M13: 14 | N13: 14 | O13: 15 | P13: 34 | Q13: 44 | R13: 44 | S13: 35 | T13: 36 | U13: 31 | V13: 31 | W13: 32 | X13: 35 | Y13: 34 | Z13: 33 | AA13: 32 | AB13: 30 | AC13: 27 | AD13: 23 | AE13: 10 | AF13: 11 | AG13: 8 | AH13: 11 | AI13: 23 | AJ13: 26 | AK13: 21 | AL13: 33 | AM13: 42 | AN13: 28 | AO13: 26 | AP13: 28 | AQ13: 19 | AR13: 25 | AS13: 27 | AT13: 23 | AU13: 20 | AV13: 17 | AW13: 14 | AX13: 17 | AY13: 12 | AZ13: 23 | BA13: 30 | BB13: 19 | BC13: 26 | BD13: 19 | BE13: 19 | BF13: 10 | BG13: 29 | BH13: 49 | BI13: 19 | BJ13: 69 | BK13: 151 | BL13: 140 | BM13: 136 | BN13: 208 | BO13: 234 | BP13: 217 | BQ13: 107 | BR13: 100 | BS13: 47 | BT13: 58 | BU13: 53 | BV13: 48 | BW13: 111 | BX13: 156 | BY13: 145 | BZ13: 148 | CA13: 244 | CB13: 251 | CC13: 249 | CD13: 219 | CE13: 137 | CF13: 103 | CG13: 169 | CH13: 249 | CI13: 250 | CJ13: 251 | CK13: 247 | CL13: 241 | CM13: 241 | CN13: 222 | CO13: 121 | CP13: 131 | CQ13: 132 | CR13: 59 | CS13: 36 | CT13: 42 | CU13: 83 | CV13: 113 | CW13: 88 | CX13: 152 | CY13: 175 | CZ13: 150 | DA13: 134 | DB13: 116 | DC13: 105 | DD13: 94 | DE13: 97 | DF13: 88 | DG13: 86 | DH13: 83 | DI13: 82 | DJ13: 84 | DK13: 83 | DL13: 79
B14: 55 | C14: 68 | D14: 58 | E14: 79 | F14: 58 | G14: 126 | H14: 203 | I14: 168 | J14: 192 | K14: 205 | L14: 56 | M14: 15 | N14: 15 | O14: 17 | P14: 16 | Q14: 8 | R14: 13 | S14: 33 | T14: 42 | U14: 48 | V14: 51 | W14: 51 | X14: 48 | Y14: 50 | Z14: 60 | AA14: 55 | AB14: 55 | AC14: 34 | AD14: 16 | AE14: 16 | AF14: 18 | AG14: 12 | AH14: 18 | AI14: 13 | AJ14: 11 | AK14: 11 | AL14: 28 | AM14: 39 | AN14: 13 | AO14: 13 | AP14: 20 | AQ14: 30 | AR14: 31 | AS14: 30 | AT14: 27 | AU14: 23 | AV14: 21 | AW14: 17 | AX14: 18 | AY14: 12 | AZ14: 41 | BA14: 42 | BB14: 33 | BC14: 76 | BD14: 56 | BE14: 11 | BF14: 6 | BG14: 21 | BH14: 46 | BI14: 36 | BJ14: 21 | BK14: 106 | BL14: 152 | BM14: 130 | BN14: 151 | BO14: 237 | BP14: 185 | BQ14: 106 | BR14: 60 | BS14: 55 | BT14: 63 | BU14: 47 | BV14: 39 | BW14: 96 | BX14: 155 | BY14: 139 | BZ14: 164 | CA14: 248 | CB14: 251 | CC14: 252 | CD14: 251 | CE14: 235 | CF14: 236 | CG14: 247 | CH14: 253 | CI14: 246 | CJ14: 250 | CK14: 242 | CL14: 238 | CM14: 240 | CN14: 149 | CO14: 125 | CP14: 138 | CQ14: 98 | CR14: 35 | CS14: 38 | CT14: 22 | CU14: 26 | CV14: 75 | CW14: 91 | CX14: 173 | CY14: 185 | CZ14: 172 | DA14: 155 | DB14: 135 | DC14: 118 | DD14: 110 | DE14: 99 | DF14: 93 | DG14: 85 | DH14: 85 | DI14: 86 | DJ14: 81 | DK14: 79 | DL14: 84
B15: 56 | C15: 30 | D15: 50 | E15: 58 | F15: 85 | G15: 70 | H15: 139 | I15: 197 | J15: 213 | K15: 155 | L15: 61 | M15: 20 | N15: 18 | O15: 25 | P15: 25 | Q15: 15 | R15: 24 | S15: 37 | T15: 17 | U15: 13 | V15: 11 | W15: 13 | X15: 17 | Y15: 18 | Z15: 18 | AA15: 16 | AB15: 16 | AC15: 20 | AD15: 24 | AE15: 18 | AF15: 15 | AG15: 11 | AH15: 13 | AI15: 16 | AJ15: 10 | AK15: 39 | AL15: 46 | AM15: 24 | AN15: 22 | AO15: 34 | AP15: 37 | AQ15: 34 | AR15: 30 | AS15: 36 | AT15: 29 | AU15: 28 | AV15: 25 | AW15: 23 | AX15: 17 | AY15: 15 | AZ15: 23 | BA15: 21 | BB15: 113 | BC15: 116 | BD15: 112 | BE15: 67 | BF15: 4 | BG15: 13 | BH15: 24 | BI15: 40 | BJ15: 26 | BK15: 36 | BL15: 134 | BM15: 150 | BN15: 128 | BO15: 161 | BP15: 152 | BQ15: 96 | BR15: 190 | BS15: 128 | BT15: 74 | BU15: 45 | BV15: 28 | BW15: 123 | BX15: 148 | BY15: 133 | BZ15: 187 | CA15: 250 | CB15: 251 | CC15: 254 | CD15: 253 | CE15: 252 | CF15: 250 | CG15: 251 | CH15: 252 | CI15: 248 | CJ15: 245 | CK15: 243 | CL15: 242 | CM15: 171 | CN15: 121 | CO15: 136 | CP15: 125 | CQ15: 53 | CR15: 45 | CS15: 34 | CT15: 16 | CU15: 9 | CV15: 50 | CW15: 80 | CX15: 186 | CY15: 184 | CZ15: 180 | DA15: 174 | DB15: 160 | DC15: 133 | DD15: 121 | DE15: 110 | DF15: 103 | DG15: 95 | DH15: 86 | DI15: 83 | DJ15: 83 | DK15: 81 | DL15: 81
... B96: 137 | C96: 33 | D96: 28 | E96: 19 | F96: 32 | G96: 21 | H96: 33 | I96: 79 | J96: 78 | K96: 94 | L96: 92 | M96: 99 | N96: 106 | O96: 108 | P96: 112 | Q96: 114 | R96: 121 | S96: 119 | T96: 125 | U96: 120 | V96: 121 | W96: 122 | X96: 125 | Y96: 121 | Z96: 119 | AA96: 113 | AB96: 107 | AC96: 108 | AD96: 107 | AE96: 100 | AF96: 93 | AG96: 87 | AH96: 86 | AI96: 91 | AJ96: 138 | AK96: 66 | AL96: 38 | AM96: 15 | AN96: 72 | AO96: 193 | AP96: 81 | AQ96: 121 | AR96: 72 | AS96: 69 | AT96: 67 | AU96: 67 | AV96: 82 | AW96: 63 | AX96: 182 | AY96: 215 | AZ96: 165 | BA96: 201 | BB96: 151 | BC96: 86 | BD96: 60 | BE96: 64 | BF96: 80 | BG96: 30 | BH96: 13 | BI96: 46 | BJ96: 34 | BK96: 45 | BL96: 85 | BM96: 222 | BN96: 198 | BO96: 114 | BP96: 118 | BQ96: 246 | BR96: 219 | BS96: 78 | BT96: 36 | BU96: 27 | BV96: 20 | BW96: 10 | BX96: 10 | BY96: 56 | BZ96: 29 | CA96: 11 | CB96: 131 | CC96: 172 | CD96: 69 | CE96: 47 | CF96: 26 | CG96: 40 | CH96: 28 | CI96: 95 | CJ96: 92 | CK96: 92 | CL96: 98 | CM96: 91 | CN96: 75 | CO96: 99 | CP96: 86 | CQ96: 95 | CR96: 95 | CS96: 101 | CT96: 96 | CU96: 99 | CV96: 91 | CW96: 79 | CX96: 65 | CY96: 66 | CZ96: 83 | DA96: 95 | DB96: 95 | DC96: 93 | DD96: 81 | DE96: 76 | DF96: 63 | DG96: 38 | DH96: 59 | DI96: 18 | DJ96: 16 | DK96: 15 | DL96: 9

Sheet Filtro_anillo
A1: Filtro de anillo: R(x, y) en un punto
A2: R = (μ_disco − μ_anillo) · compuerta, con compuerta = clip((Gmax − μ_anillo)/Gmax, 0, 1); resultado truncado a entero 0–255 (uint8).
B4: x centro (px de análisis) | C4: 179 | D4: Editable. Robot 3: (179, 84). Hueco entre robots: (216, 100).
B5: y centro (px de análisis) | C5: 84
B6: μ_disco (gris medio del disco) | C6: =SUMPRODUCT(INDEX(ImgA,C5-ImgA_y0+1-25,C4-ImgA_x0+1-25):INDEX(ImgA,C5-ImgA_y0+1+25,C4-ImgA_x0+1+25),Disco)/SUM(Disco) -> 126.56418 | D6: Promedio de los píxeles dentro de r_int_a (máscara Disco, abajo). cv2.filter2D con el núcleo normalizado.
B7: μ_anillo (gris medio del anillo) | C7: =SUMPRODUCT(INDEX(ImgA,C5-ImgA_y0+1-25,C4-ImgA_x0+1-25):INDEX(ImgA,C5-ImgA_y0+1+25,C4-ImgA_x0+1+25),Anillo)/SUM(Anillo) -> 64.064721 | D7: Promedio de los píxeles entre r_int_a y r_ext_a (máscara Anillo).
B8: contraste μ_disco − μ_anillo | C8: =C6-C7 -> 62.499458 | D8: Grande y positivo si hay un disco claro rodeado de un anillo oscuro.
B9: compuerta | C9: =MIN(1,MAX(0,(Gmax-C7)/Gmax)) -> 0.39561584 | D9: 1 si el anillo es negro; 0 si su gris medio supera Gmax.
B10: R | C10: =INT(MIN(255,MAX(0,C8*C9))) -> 24 | D10: Respuesta del filtro en este píxel (la app la guarda como uint8).
B11: R con la app (referencia) | C11: =IF(AND(C4=179,C5=84),24,IF(AND(C4=216,C5=100),14,"—")) -> 24 | D11: Valor que da detection.robot_response en Python sobre la misma imagen (solo para los dos puntos de ejemplo).
B12: píxeles del disco / del anillo | C12: =SUM(Disco)&" / "&SUM(Anillo) -> 1005 / 788
B15: Máscaras (51 × 51, centradas en el píxel evaluado)
B16: Disco: distancia ≤ r_int_a. Anillo: r_int_a < distancia ≤ r_ext_a. Los encabezados son el desplazamiento dx (fila 18) y dy (columna a la izquierda de cada máscara).
F17: Disco | BG17: Anillo
F18: -25 | G18: -24 | H18: -23 | I18: -22 | J18: -21 | K18: -20 | L18: -19 | M18: -18 | N18: -17 | O18: -16 | P18: -15 | Q18: -14 | R18: -13 | S18: -12 | T18: -11 | U18: -10 | V18: -9 | W18: -8 | X18: -7 | Y18: -6 | Z18: -5 | AA18: -4 | AB18: -3 | AC18: -2 | AD18: -1 | AE18: 0 | AF18: 1 | AG18: 2 | AH18: 3 | AI18: 4 | AJ18: 5 | AK18: 6 | AL18: 7 | AM18: 8 | AN18: 9 | AO18: 10 | AP18: 11 | AQ18: 12 | AR18: 13 | AS18: 14 | AT18: 15 | AU18: 16 | AV18: 17 | AW18: 18 | AX18: 19 | AY18: 20 | AZ18: 21 | BA18: 22 | BB18: 23 | BC18: 24 | BD18: 25 | BG18: -25 | BH18: -24 | BI18: -23 | BJ18: -22 | BK18: -21 | BL18: -20 | BM18: -19 | BN18: -18 | BO18: -17 | BP18: -16 | BQ18: -15 | BR18: -14 | BS18: -13 | BT18: -12 | BU18: -11 | BV18: -10 | BW18: -9 | BX18: -8 | BY18: -7 | BZ18: -6 | CA18: -5 | CB18: -4 | CC18: -3 | CD18: -2 | CE18: -1 | CF18: 0 | CG18: 1 | CH18: 2 | CI18: 3 | CJ18: 4 | CK18: 5 | CL18: 6 | CM18: 7 | CN18: 8 | CO18: 9 | CP18: 10 | CQ18: 11 | CR18: 12 | CS18: 13 | CT18: 14 | CU18: 15 | CV18: 16 | CW18: 17 | CX18: 18 | CY18: 19 | CZ18: 20 | DA18: 21 | DB18: 22 | DC18: 23 | DD18: 24 | DE18: 25
E19: -25 | F19: =IF(SQRT(F$18^2+$E19^2)<=r_int_a,1,0) -> 0 | G19: =IF(SQRT(G$18^2+$E19^2)<=r_int_a,1,0) -> 0 | H19: =IF(SQRT(H$18^2+$E19^2)<=r_int_a,1,0) -> 0 | I19: =IF(SQRT(I$18^2+$E19^2)<=r_int_a,1,0) -> 0 | J19: =IF(SQRT(J$18^2+$E19^2)<=r_int_a,1,0) -> 0 | K19: =IF(SQRT(K$18^2+$E19^2)<=r_int_a,1,0) -> 0 | L19: =IF(SQRT(L$18^2+$E19^2)<=r_int_a,1,0) -> 0 | M19: =IF(SQRT(M$18^2+$E19^2)<=r_int_a,1,0) -> 0 | ... BD19: =IF(SQRT(BD$18^2+$E19^2)<=r_int_a,1,0) -> 0 | BF19: -25 | BG19: =IF(AND(SQRT(BG$18^2+$E19^2)>r_int_a,SQRT(BG$18^2+$E19^2)<=r_ext_a),1,0) -> 0 | BH19: =IF(AND(SQRT(BH$18^2+$E19^2)>r_int_a,SQRT(BH$18^2+$E19^2)<=r_ext_a),1,0) -> 0 | BI19: =IF(AND(SQRT(BI$18^2+$E19^2)>r_int_a,SQRT(BI$18^2+$E19^2)<=r_ext_a),1,0) -> 0 | BJ19: =IF(AND(SQRT(BJ$18^2+$E19^2)>r_int_a,SQRT(BJ$18^2+$E19^2)<=r_ext_a),1,0) -> 0 | BK19: =IF(AND(SQRT(BK$18^2+$E19^2)>r_int_a,SQRT(BK$18^2+$E19^2)<=r_ext_a),1,0) -> 0 | BL19: =IF(AND(SQRT(BL$18^2+$E19^2)>r_int_a,SQRT(BL$18^2+$E19^2)<=r_ext_a),1,0) -> 0 | BM19: =IF(AND(SQRT(BM$18^2+$E19^2)>r_int_a,SQRT(BM$18^2+$E19^2)<=r_ext_a),1,0) -> 0 | BN19: =IF(AND(SQRT(BN$18^2+$E19^2)>r_int_a,SQRT(BN$18^2+$E19^2)<=r_ext_a),1,0) -> 0 | ... DE19: =IF(AND(SQRT(DE$18^2+$E19^2)>r_int_a,SQRT(DE$18^2+$E19^2)<=r_ext_a),1,0) -> 0
E20: -24 | F20: =IF(SQRT(F$18^2+$E20^2)<=r_int_a,1,0) -> 0 | G20: =IF(SQRT(G$18^2+$E20^2)<=r_int_a,1,0) -> 0 | H20: =IF(SQRT(H$18^2+$E20^2)<=r_int_a,1,0) -> 0 | I20: =IF(SQRT(I$18^2+$E20^2)<=r_int_a,1,0) -> 0 | J20: =IF(SQRT(J$18^2+$E20^2)<=r_int_a,1,0) -> 0 | K20: =IF(SQRT(K$18^2+$E20^2)<=r_int_a,1,0) -> 0 | L20: =IF(SQRT(L$18^2+$E20^2)<=r_int_a,1,0) -> 0 | M20: =IF(SQRT(M$18^2+$E20^2)<=r_int_a,1,0) -> 0 | ... BD20: =IF(SQRT(BD$18^2+$E20^2)<=r_int_a,1,0) -> 0 | BF20: -24 | BG20: =IF(AND(SQRT(BG$18^2+$E20^2)>r_int_a,SQRT(BG$18^2+$E20^2)<=r_ext_a),1,0) -> 0 | BH20: =IF(AND(SQRT(BH$18^2+$E20^2)>r_int_a,SQRT(BH$18^2+$E20^2)<=r_ext_a),1,0) -> 0 | BI20: =IF(AND(SQRT(BI$18^2+$E20^2)>r_int_a,SQRT(BI$18^2+$E20^2)<=r_ext_a),1,0) -> 0 | BJ20: =IF(AND(SQRT(BJ$18^2+$E20^2)>r_int_a,SQRT(BJ$18^2+$E20^2)<=r_ext_a),1,0) -> 0 | BK20: =IF(AND(SQRT(BK$18^2+$E20^2)>r_int_a,SQRT(BK$18^2+$E20^2)<=r_ext_a),1,0) -> 0 | BL20: =IF(AND(SQRT(BL$18^2+$E20^2)>r_int_a,SQRT(BL$18^2+$E20^2)<=r_ext_a),1,0) -> 0 | BM20: =IF(AND(SQRT(BM$18^2+$E20^2)>r_int_a,SQRT(BM$18^2+$E20^2)<=r_ext_a),1,0) -> 0 | BN20: =IF(AND(SQRT(BN$18^2+$E20^2)>r_int_a,SQRT(BN$18^2+$E20^2)<=r_ext_a),1,0) -> 0 | ... DE20: =IF(AND(SQRT(DE$18^2+$E20^2)>r_int_a,SQRT(DE$18^2+$E20^2)<=r_ext_a),1,0) -> 0
E21: -23 | F21: =IF(SQRT(F$18^2+$E21^2)<=r_int_a,1,0) -> 0 | G21: =IF(SQRT(G$18^2+$E21^2)<=r_int_a,1,0) -> 0 | H21: =IF(SQRT(H$18^2+$E21^2)<=r_int_a,1,0) -> 0 | I21: =IF(SQRT(I$18^2+$E21^2)<=r_int_a,1,0) -> 0 | J21: =IF(SQRT(J$18^2+$E21^2)<=r_int_a,1,0) -> 0 | K21: =IF(SQRT(K$18^2+$E21^2)<=r_int_a,1,0) -> 0 | L21: =IF(SQRT(L$18^2+$E21^2)<=r_int_a,1,0) -> 0 | M21: =IF(SQRT(M$18^2+$E21^2)<=r_int_a,1,0) -> 0 | ... BD21: =IF(SQRT(BD$18^2+$E21^2)<=r_int_a,1,0) -> 0 | BF21: -23 | BG21: =IF(AND(SQRT(BG$18^2+$E21^2)>r_int_a,SQRT(BG$18^2+$E21^2)<=r_ext_a),1,0) -> 0 | BH21: =IF(AND(SQRT(BH$18^2+$E21^2)>r_int_a,SQRT(BH$18^2+$E21^2)<=r_ext_a),1,0) -> 0 | BI21: =IF(AND(SQRT(BI$18^2+$E21^2)>r_int_a,SQRT(BI$18^2+$E21^2)<=r_ext_a),1,0) -> 0 | BJ21: =IF(AND(SQRT(BJ$18^2+$E21^2)>r_int_a,SQRT(BJ$18^2+$E21^2)<=r_ext_a),1,0) -> 0 | BK21: =IF(AND(SQRT(BK$18^2+$E21^2)>r_int_a,SQRT(BK$18^2+$E21^2)<=r_ext_a),1,0) -> 0 | BL21: =IF(AND(SQRT(BL$18^2+$E21^2)>r_int_a,SQRT(BL$18^2+$E21^2)<=r_ext_a),1,0) -> 0 | BM21: =IF(AND(SQRT(BM$18^2+$E21^2)>r_int_a,SQRT(BM$18^2+$E21^2)<=r_ext_a),1,0) -> 0 | BN21: =IF(AND(SQRT(BN$18^2+$E21^2)>r_int_a,SQRT(BN$18^2+$E21^2)<=r_ext_a),1,0) -> 0 | ... DE21: =IF(AND(SQRT(DE$18^2+$E21^2)>r_int_a,SQRT(DE$18^2+$E21^2)<=r_ext_a),1,0) -> 0
E22: -22 | F22: =IF(SQRT(F$18^2+$E22^2)<=r_int_a,1,0) -> 0 | G22: =IF(SQRT(G$18^2+$E22^2)<=r_int_a,1,0) -> 0 | H22: =IF(SQRT(H$18^2+$E22^2)<=r_int_a,1,0) -> 0 | I22: =IF(SQRT(I$18^2+$E22^2)<=r_int_a,1,0) -> 0 | J22: =IF(SQRT(J$18^2+$E22^2)<=r_int_a,1,0) -> 0 | K22: =IF(SQRT(K$18^2+$E22^2)<=r_int_a,1,0) -> 0 | L22: =IF(SQRT(L$18^2+$E22^2)<=r_int_a,1,0) -> 0 | M22: =IF(SQRT(M$18^2+$E22^2)<=r_int_a,1,0) -> 0 | ... BD22: =IF(SQRT(BD$18^2+$E22^2)<=r_int_a,1,0) -> 0 | BF22: -22 | BG22: =IF(AND(SQRT(BG$18^2+$E22^2)>r_int_a,SQRT(BG$18^2+$E22^2)<=r_ext_a),1,0) -> 0 | BH22: =IF(AND(SQRT(BH$18^2+$E22^2)>r_int_a,SQRT(BH$18^2+$E22^2)<=r_ext_a),1,0) -> 0 | BI22: =IF(AND(SQRT(BI$18^2+$E22^2)>r_int_a,SQRT(BI$18^2+$E22^2)<=r_ext_a),1,0) -> 0 | BJ22: =IF(AND(SQRT(BJ$18^2+$E22^2)>r_int_a,SQRT(BJ$18^2+$E22^2)<=r_ext_a),1,0) -> 0 | BK22: =IF(AND(SQRT(BK$18^2+$E22^2)>r_int_a,SQRT(BK$18^2+$E22^2)<=r_ext_a),1,0) -> 0 | BL22: =IF(AND(SQRT(BL$18^2+$E22^2)>r_int_a,SQRT(BL$18^2+$E22^2)<=r_ext_a),1,0) -> 0 | BM22: =IF(AND(SQRT(BM$18^2+$E22^2)>r_int_a,SQRT(BM$18^2+$E22^2)<=r_ext_a),1,0) -> 0 | BN22: =IF(AND(SQRT(BN$18^2+$E22^2)>r_int_a,SQRT(BN$18^2+$E22^2)<=r_ext_a),1,0) -> 0 | ... DE22: =IF(AND(SQRT(DE$18^2+$E22^2)>r_int_a,SQRT(DE$18^2+$E22^2)<=r_ext_a),1,0) -> 0
E23: -21 | F23: =IF(SQRT(F$18^2+$E23^2)<=r_int_a,1,0) -> 0 | G23: =IF(SQRT(G$18^2+$E23^2)<=r_int_a,1,0) -> 0 | H23: =IF(SQRT(H$18^2+$E23^2)<=r_int_a,1,0) -> 0 | I23: =IF(SQRT(I$18^2+$E23^2)<=r_int_a,1,0) -> 0 | J23: =IF(SQRT(J$18^2+$E23^2)<=r_int_a,1,0) -> 0 | K23: =IF(SQRT(K$18^2+$E23^2)<=r_int_a,1,0) -> 0 | L23: =IF(SQRT(L$18^2+$E23^2)<=r_int_a,1,0) -> 0 | M23: =IF(SQRT(M$18^2+$E23^2)<=r_int_a,1,0) -> 0 | ... BD23: =IF(SQRT(BD$18^2+$E23^2)<=r_int_a,1,0) -> 0 | BF23: -21 | BG23: =IF(AND(SQRT(BG$18^2+$E23^2)>r_int_a,SQRT(BG$18^2+$E23^2)<=r_ext_a),1,0) -> 0 | BH23: =IF(AND(SQRT(BH$18^2+$E23^2)>r_int_a,SQRT(BH$18^2+$E23^2)<=r_ext_a),1,0) -> 0 | BI23: =IF(AND(SQRT(BI$18^2+$E23^2)>r_int_a,SQRT(BI$18^2+$E23^2)<=r_ext_a),1,0) -> 0 | BJ23: =IF(AND(SQRT(BJ$18^2+$E23^2)>r_int_a,SQRT(BJ$18^2+$E23^2)<=r_ext_a),1,0) -> 0 | BK23: =IF(AND(SQRT(BK$18^2+$E23^2)>r_int_a,SQRT(BK$18^2+$E23^2)<=r_ext_a),1,0) -> 0 | BL23: =IF(AND(SQRT(BL$18^2+$E23^2)>r_int_a,SQRT(BL$18^2+$E23^2)<=r_ext_a),1,0) -> 0 | BM23: =IF(AND(SQRT(BM$18^2+$E23^2)>r_int_a,SQRT(BM$18^2+$E23^2)<=r_ext_a),1,0) -> 0 | BN23: =IF(AND(SQRT(BN$18^2+$E23^2)>r_int_a,SQRT(BN$18^2+$E23^2)<=r_ext_a),1,0) -> 0 | ... DE23: =IF(AND(SQRT(DE$18^2+$E23^2)>r_int_a,SQRT(DE$18^2+$E23^2)<=r_ext_a),1,0) -> 0
E24: -20 | F24: =IF(SQRT(F$18^2+$E24^2)<=r_int_a,1,0) -> 0 | G24: =IF(SQRT(G$18^2+$E24^2)<=r_int_a,1,0) -> 0 | H24: =IF(SQRT(H$18^2+$E24^2)<=r_int_a,1,0) -> 0 | I24: =IF(SQRT(I$18^2+$E24^2)<=r_int_a,1,0) -> 0 | J24: =IF(SQRT(J$18^2+$E24^2)<=r_int_a,1,0) -> 0 | K24: =IF(SQRT(K$18^2+$E24^2)<=r_int_a,1,0) -> 0 | L24: =IF(SQRT(L$18^2+$E24^2)<=r_int_a,1,0) -> 0 | M24: =IF(SQRT(M$18^2+$E24^2)<=r_int_a,1,0) -> 0 | ... BD24: =IF(SQRT(BD$18^2+$E24^2)<=r_int_a,1,0) -> 0 | BF24: -20 | BG24: =IF(AND(SQRT(BG$18^2+$E24^2)>r_int_a,SQRT(BG$18^2+$E24^2)<=r_ext_a),1,0) -> 0 | BH24: =IF(AND(SQRT(BH$18^2+$E24^2)>r_int_a,SQRT(BH$18^2+$E24^2)<=r_ext_a),1,0) -> 0 | BI24: =IF(AND(SQRT(BI$18^2+$E24^2)>r_int_a,SQRT(BI$18^2+$E24^2)<=r_ext_a),1,0) -> 0 | BJ24: =IF(AND(SQRT(BJ$18^2+$E24^2)>r_int_a,SQRT(BJ$18^2+$E24^2)<=r_ext_a),1,0) -> 0 | BK24: =IF(AND(SQRT(BK$18^2+$E24^2)>r_int_a,SQRT(BK$18^2+$E24^2)<=r_ext_a),1,0) -> 0 | BL24: =IF(AND(SQRT(BL$18^2+$E24^2)>r_int_a,SQRT(BL$18^2+$E24^2)<=r_ext_a),1,0) -> 0 | BM24: =IF(AND(SQRT(BM$18^2+$E24^2)>r_int_a,SQRT(BM$18^2+$E24^2)<=r_ext_a),1,0) -> 0 | BN24: =IF(AND(SQRT(BN$18^2+$E24^2)>r_int_a,SQRT(BN$18^2+$E24^2)<=r_ext_a),1,0) -> 0 | ... DE24: =IF(AND(SQRT(DE$18^2+$E24^2)>r_int_a,SQRT(DE$18^2+$E24^2)<=r_ext_a),1,0) -> 0
E25: -19 | F25: =IF(SQRT(F$18^2+$E25^2)<=r_int_a,1,0) -> 0 | G25: =IF(SQRT(G$18^2+$E25^2)<=r_int_a,1,0) -> 0 | H25: =IF(SQRT(H$18^2+$E25^2)<=r_int_a,1,0) -> 0 | I25: =IF(SQRT(I$18^2+$E25^2)<=r_int_a,1,0) -> 0 | J25: =IF(SQRT(J$18^2+$E25^2)<=r_int_a,1,0) -> 0 | K25: =IF(SQRT(K$18^2+$E25^2)<=r_int_a,1,0) -> 0 | L25: =IF(SQRT(L$18^2+$E25^2)<=r_int_a,1,0) -> 0 | M25: =IF(SQRT(M$18^2+$E25^2)<=r_int_a,1,0) -> 0 | ... BD25: =IF(SQRT(BD$18^2+$E25^2)<=r_int_a,1,0) -> 0 | BF25: -19 | BG25: =IF(AND(SQRT(BG$18^2+$E25^2)>r_int_a,SQRT(BG$18^2+$E25^2)<=r_ext_a),1,0) -> 0 | BH25: =IF(AND(SQRT(BH$18^2+$E25^2)>r_int_a,SQRT(BH$18^2+$E25^2)<=r_ext_a),1,0) -> 0 | BI25: =IF(AND(SQRT(BI$18^2+$E25^2)>r_int_a,SQRT(BI$18^2+$E25^2)<=r_ext_a),1,0) -> 0 | BJ25: =IF(AND(SQRT(BJ$18^2+$E25^2)>r_int_a,SQRT(BJ$18^2+$E25^2)<=r_ext_a),1,0) -> 0 | BK25: =IF(AND(SQRT(BK$18^2+$E25^2)>r_int_a,SQRT(BK$18^2+$E25^2)<=r_ext_a),1,0) -> 0 | BL25: =IF(AND(SQRT(BL$18^2+$E25^2)>r_int_a,SQRT(BL$18^2+$E25^2)<=r_ext_a),1,0) -> 0 | BM25: =IF(AND(SQRT(BM$18^2+$E25^2)>r_int_a,SQRT(BM$18^2+$E25^2)<=r_ext_a),1,0) -> 0 | BN25: =IF(AND(SQRT(BN$18^2+$E25^2)>r_int_a,SQRT(BN$18^2+$E25^2)<=r_ext_a),1,0) -> 0 | ... DE25: =IF(AND(SQRT(DE$18^2+$E25^2)>r_int_a,SQRT(DE$18^2+$E25^2)<=r_ext_a),1,0) -> 0
E26: -18 | F26: =IF(SQRT(F$18^2+$E26^2)<=r_int_a,1,0) -> 0 | G26: =IF(SQRT(G$18^2+$E26^2)<=r_int_a,1,0) -> 0 | H26: =IF(SQRT(H$18^2+$E26^2)<=r_int_a,1,0) -> 0 | I26: =IF(SQRT(I$18^2+$E26^2)<=r_int_a,1,0) -> 0 | J26: =IF(SQRT(J$18^2+$E26^2)<=r_int_a,1,0) -> 0 | K26: =IF(SQRT(K$18^2+$E26^2)<=r_int_a,1,0) -> 0 | L26: =IF(SQRT(L$18^2+$E26^2)<=r_int_a,1,0) -> 0 | M26: =IF(SQRT(M$18^2+$E26^2)<=r_int_a,1,0) -> 0 | ... BD26: =IF(SQRT(BD$18^2+$E26^2)<=r_int_a,1,0) -> 0 | BF26: -18 | BG26: =IF(AND(SQRT(BG$18^2+$E26^2)>r_int_a,SQRT(BG$18^2+$E26^2)<=r_ext_a),1,0) -> 0 | BH26: =IF(AND(SQRT(BH$18^2+$E26^2)>r_int_a,SQRT(BH$18^2+$E26^2)<=r_ext_a),1,0) -> 0 | BI26: =IF(AND(SQRT(BI$18^2+$E26^2)>r_int_a,SQRT(BI$18^2+$E26^2)<=r_ext_a),1,0) -> 0 | BJ26: =IF(AND(SQRT(BJ$18^2+$E26^2)>r_int_a,SQRT(BJ$18^2+$E26^2)<=r_ext_a),1,0) -> 0 | BK26: =IF(AND(SQRT(BK$18^2+$E26^2)>r_int_a,SQRT(BK$18^2+$E26^2)<=r_ext_a),1,0) -> 0 | BL26: =IF(AND(SQRT(BL$18^2+$E26^2)>r_int_a,SQRT(BL$18^2+$E26^2)<=r_ext_a),1,0) -> 0 | BM26: =IF(AND(SQRT(BM$18^2+$E26^2)>r_int_a,SQRT(BM$18^2+$E26^2)<=r_ext_a),1,0) -> 0 | BN26: =IF(AND(SQRT(BN$18^2+$E26^2)>r_int_a,SQRT(BN$18^2+$E26^2)<=r_ext_a),1,0) -> 0 | ... DE26: =IF(AND(SQRT(DE$18^2+$E26^2)>r_int_a,SQRT(DE$18^2+$E26^2)<=r_ext_a),1,0) -> 0
E27: -17 | F27: =IF(SQRT(F$18^2+$E27^2)<=r_int_a,1,0) -> 0 | G27: =IF(SQRT(G$18^2+$E27^2)<=r_int_a,1,0) -> 0 | H27: =IF(SQRT(H$18^2+$E27^2)<=r_int_a,1,0) -> 0 | I27: =IF(SQRT(I$18^2+$E27^2)<=r_int_a,1,0) -> 0 | J27: =IF(SQRT(J$18^2+$E27^2)<=r_int_a,1,0) -> 0 | K27: =IF(SQRT(K$18^2+$E27^2)<=r_int_a,1,0) -> 0 | L27: =IF(SQRT(L$18^2+$E27^2)<=r_int_a,1,0) -> 0 | M27: =IF(SQRT(M$18^2+$E27^2)<=r_int_a,1,0) -> 0 | ... BD27: =IF(SQRT(BD$18^2+$E27^2)<=r_int_a,1,0) -> 0 | BF27: -17 | BG27: =IF(AND(SQRT(BG$18^2+$E27^2)>r_int_a,SQRT(BG$18^2+$E27^2)<=r_ext_a),1,0) -> 0 | BH27: =IF(AND(SQRT(BH$18^2+$E27^2)>r_int_a,SQRT(BH$18^2+$E27^2)<=r_ext_a),1,0) -> 0 | BI27: =IF(AND(SQRT(BI$18^2+$E27^2)>r_int_a,SQRT(BI$18^2+$E27^2)<=r_ext_a),1,0) -> 0 | BJ27: =IF(AND(SQRT(BJ$18^2+$E27^2)>r_int_a,SQRT(BJ$18^2+$E27^2)<=r_ext_a),1,0) -> 0 | BK27: =IF(AND(SQRT(BK$18^2+$E27^2)>r_int_a,SQRT(BK$18^2+$E27^2)<=r_ext_a),1,0) -> 0 | BL27: =IF(AND(SQRT(BL$18^2+$E27^2)>r_int_a,SQRT(BL$18^2+$E27^2)<=r_ext_a),1,0) -> 0 | BM27: =IF(AND(SQRT(BM$18^2+$E27^2)>r_int_a,SQRT(BM$18^2+$E27^2)<=r_ext_a),1,0) -> 0 | BN27: =IF(AND(SQRT(BN$18^2+$E27^2)>r_int_a,SQRT(BN$18^2+$E27^2)<=r_ext_a),1,0) -> 0 | ... DE27: =IF(AND(SQRT(DE$18^2+$E27^2)>r_int_a,SQRT(DE$18^2+$E27^2)<=r_ext_a),1,0) -> 0
E28: -16 | F28: =IF(SQRT(F$18^2+$E28^2)<=r_int_a,1,0) -> 0 | G28: =IF(SQRT(G$18^2+$E28^2)<=r_int_a,1,0) -> 0 | H28: =IF(SQRT(H$18^2+$E28^2)<=r_int_a,1,0) -> 0 | I28: =IF(SQRT(I$18^2+$E28^2)<=r_int_a,1,0) -> 0 | J28: =IF(SQRT(J$18^2+$E28^2)<=r_int_a,1,0) -> 0 | K28: =IF(SQRT(K$18^2+$E28^2)<=r_int_a,1,0) -> 0 | L28: =IF(SQRT(L$18^2+$E28^2)<=r_int_a,1,0) -> 0 | M28: =IF(SQRT(M$18^2+$E28^2)<=r_int_a,1,0) -> 0 | ... BD28: =IF(SQRT(BD$18^2+$E28^2)<=r_int_a,1,0) -> 0 | BF28: -16 | BG28: =IF(AND(SQRT(BG$18^2+$E28^2)>r_int_a,SQRT(BG$18^2+$E28^2)<=r_ext_a),1,0) -> 0 | BH28: =IF(AND(SQRT(BH$18^2+$E28^2)>r_int_a,SQRT(BH$18^2+$E28^2)<=r_ext_a),1,0) -> 0 | BI28: =IF(AND(SQRT(BI$18^2+$E28^2)>r_int_a,SQRT(BI$18^2+$E28^2)<=r_ext_a),1,0) -> 0 | BJ28: =IF(AND(SQRT(BJ$18^2+$E28^2)>r_int_a,SQRT(BJ$18^2+$E28^2)<=r_ext_a),1,0) -> 0 | BK28: =IF(AND(SQRT(BK$18^2+$E28^2)>r_int_a,SQRT(BK$18^2+$E28^2)<=r_ext_a),1,0) -> 0 | BL28: =IF(AND(SQRT(BL$18^2+$E28^2)>r_int_a,SQRT(BL$18^2+$E28^2)<=r_ext_a),1,0) -> 0 | BM28: =IF(AND(SQRT(BM$18^2+$E28^2)>r_int_a,SQRT(BM$18^2+$E28^2)<=r_ext_a),1,0) -> 0 | BN28: =IF(AND(SQRT(BN$18^2+$E28^2)>r_int_a,SQRT(BN$18^2+$E28^2)<=r_ext_a),1,0) -> 0 | ... DE28: =IF(AND(SQRT(DE$18^2+$E28^2)>r_int_a,SQRT(DE$18^2+$E28^2)<=r_ext_a),1,0) -> 0
E29: -15 | F29: =IF(SQRT(F$18^2+$E29^2)<=r_int_a,1,0) -> 0 | G29: =IF(SQRT(G$18^2+$E29^2)<=r_int_a,1,0) -> 0 | H29: =IF(SQRT(H$18^2+$E29^2)<=r_int_a,1,0) -> 0 | I29: =IF(SQRT(I$18^2+$E29^2)<=r_int_a,1,0) -> 0 | J29: =IF(SQRT(J$18^2+$E29^2)<=r_int_a,1,0) -> 0 | K29: =IF(SQRT(K$18^2+$E29^2)<=r_int_a,1,0) -> 0 | L29: =IF(SQRT(L$18^2+$E29^2)<=r_int_a,1,0) -> 0 | M29: =IF(SQRT(M$18^2+$E29^2)<=r_int_a,1,0) -> 0 | ... BD29: =IF(SQRT(BD$18^2+$E29^2)<=r_int_a,1,0) -> 0 | BF29: -15 | BG29: =IF(AND(SQRT(BG$18^2+$E29^2)>r_int_a,SQRT(BG$18^2+$E29^2)<=r_ext_a),1,0) -> 0 | BH29: =IF(AND(SQRT(BH$18^2+$E29^2)>r_int_a,SQRT(BH$18^2+$E29^2)<=r_ext_a),1,0) -> 0 | BI29: =IF(AND(SQRT(BI$18^2+$E29^2)>r_int_a,SQRT(BI$18^2+$E29^2)<=r_ext_a),1,0) -> 0 | BJ29: =IF(AND(SQRT(BJ$18^2+$E29^2)>r_int_a,SQRT(BJ$18^2+$E29^2)<=r_ext_a),1,0) -> 0 | BK29: =IF(AND(SQRT(BK$18^2+$E29^2)>r_int_a,SQRT(BK$18^2+$E29^2)<=r_ext_a),1,0) -> 0 | BL29: =IF(AND(SQRT(BL$18^2+$E29^2)>r_int_a,SQRT(BL$18^2+$E29^2)<=r_ext_a),1,0) -> 0 | BM29: =IF(AND(SQRT(BM$18^2+$E29^2)>r_int_a,SQRT(BM$18^2+$E29^2)<=r_ext_a),1,0) -> 0 | BN29: =IF(AND(SQRT(BN$18^2+$E29^2)>r_int_a,SQRT(BN$18^2+$E29^2)<=r_ext_a),1,0) -> 1 | ... DE29: =IF(AND(SQRT(DE$18^2+$E29^2)>r_int_a,SQRT(DE$18^2+$E29^2)<=r_ext_a),1,0) -> 0
E30: -14 | F30: =IF(SQRT(F$18^2+$E30^2)<=r_int_a,1,0) -> 0 | G30: =IF(SQRT(G$18^2+$E30^2)<=r_int_a,1,0) -> 0 | H30: =IF(SQRT(H$18^2+$E30^2)<=r_int_a,1,0) -> 0 | I30: =IF(SQRT(I$18^2+$E30^2)<=r_int_a,1,0) -> 0 | J30: =IF(SQRT(J$18^2+$E30^2)<=r_int_a,1,0) -> 0 | K30: =IF(SQRT(K$18^2+$E30^2)<=r_int_a,1,0) -> 0 | L30: =IF(SQRT(L$18^2+$E30^2)<=r_int_a,1,0) -> 0 | M30: =IF(SQRT(M$18^2+$E30^2)<=r_int_a,1,0) -> 0 | ... BD30: =IF(SQRT(BD$18^2+$E30^2)<=r_int_a,1,0) -> 0 | BF30: -14 | BG30: =IF(AND(SQRT(BG$18^2+$E30^2)>r_int_a,SQRT(BG$18^2+$E30^2)<=r_ext_a),1,0) -> 0 | BH30: =IF(AND(SQRT(BH$18^2+$E30^2)>r_int_a,SQRT(BH$18^2+$E30^2)<=r_ext_a),1,0) -> 0 | BI30: =IF(AND(SQRT(BI$18^2+$E30^2)>r_int_a,SQRT(BI$18^2+$E30^2)<=r_ext_a),1,0) -> 0 | BJ30: =IF(AND(SQRT(BJ$18^2+$E30^2)>r_int_a,SQRT(BJ$18^2+$E30^2)<=r_ext_a),1,0) -> 0 | BK30: =IF(AND(SQRT(BK$18^2+$E30^2)>r_int_a,SQRT(BK$18^2+$E30^2)<=r_ext_a),1,0) -> 0 | BL30: =IF(AND(SQRT(BL$18^2+$E30^2)>r_int_a,SQRT(BL$18^2+$E30^2)<=r_ext_a),1,0) -> 0 | BM30: =IF(AND(SQRT(BM$18^2+$E30^2)>r_int_a,SQRT(BM$18^2+$E30^2)<=r_ext_a),1,0) -> 1 | BN30: =IF(AND(SQRT(BN$18^2+$E30^2)>r_int_a,SQRT(BN$18^2+$E30^2)<=r_ext_a),1,0) -> 1 | ... DE30: =IF(AND(SQRT(DE$18^2+$E30^2)>r_int_a,SQRT(DE$18^2+$E30^2)<=r_ext_a),1,0) -> 0
... E69: 25 | F69: =IF(SQRT(F$18^2+$E69^2)<=r_int_a,1,0) -> 0 | G69: =IF(SQRT(G$18^2+$E69^2)<=r_int_a,1,0) -> 0 | H69: =IF(SQRT(H$18^2+$E69^2)<=r_int_a,1,0) -> 0 | I69: =IF(SQRT(I$18^2+$E69^2)<=r_int_a,1,0) -> 0 | J69: =IF(SQRT(J$18^2+$E69^2)<=r_int_a,1,0) -> 0 | K69: =IF(SQRT(K$18^2+$E69^2)<=r_int_a,1,0) -> 0 | L69: =IF(SQRT(L$18^2+$E69^2)<=r_int_a,1,0) -> 0 | M69: =IF(SQRT(M$18^2+$E69^2)<=r_int_a,1,0) -> 0 | ... BD69: =IF(SQRT(BD$18^2+$E69^2)<=r_int_a,1,0) -> 0 | BF69: 25 | BG69: =IF(AND(SQRT(BG$18^2+$E69^2)>r_int_a,SQRT(BG$18^2+$E69^2)<=r_ext_a),1,0) -> 0 | BH69: =IF(AND(SQRT(BH$18^2+$E69^2)>r_int_a,SQRT(BH$18^2+$E69^2)<=r_ext_a),1,0) -> 0 | BI69: =IF(AND(SQRT(BI$18^2+$E69^2)>r_int_a,SQRT(BI$18^2+$E69^2)<=r_ext_a),1,0) -> 0 | BJ69: =IF(AND(SQRT(BJ$18^2+$E69^2)>r_int_a,SQRT(BJ$18^2+$E69^2)<=r_ext_a),1,0) -> 0 | BK69: =IF(AND(SQRT(BK$18^2+$E69^2)>r_int_a,SQRT(BK$18^2+$E69^2)<=r_ext_a),1,0) -> 0 | BL69: =IF(AND(SQRT(BL$18^2+$E69^2)>r_int_a,SQRT(BL$18^2+$E69^2)<=r_ext_a),1,0) -> 0 | BM69: =IF(AND(SQRT(BM$18^2+$E69^2)>r_int_a,SQRT(BM$18^2+$E69^2)<=r_ext_a),1,0) -> 0 | BN69: =IF(AND(SQRT(BN$18^2+$E69^2)>r_int_a,SQRT(BN$18^2+$E69^2)<=r_ext_a),1,0) -> 0 | ... DE69: =IF(AND(SQRT(DE$18^2+$E69^2)>r_int_a,SQRT(DE$18^2+$E69^2)<=r_ext_a),1,0) -> 0

Sheet Mapa_R
A1: Mapa de respuesta R(x, y) y centro de la mancha (lo que hace trackpy.locate)
A2: Cada celda repite el cálculo de Filtro_anillo en ese píxel. El robot da una mancha ancha de R ≈ 20–48; el hueco entre robots, una mancha débil (≈ 14).
C6: μ_disco | BQ6: Centro de la mancha (≈ trackpy)
C7: 166 | D7: 167 | E7: 168 | F7: 169 | G7: 170 | H7: 171 | I7: 172 | J7: 173 | K7: 174 | L7: 175 | M7: 176 | N7: 177 | O7: 178 | P7: 179 | Q7: 180 | R7: 181 | S7: 182 | T7: 183 | U7: 184 | V7: 185 | W7: 186 | X7: 187 | Y7: 188 | Z7: 189 | AA7: 190 | AB7: 191 | AC7: 192 | AD7: 193 | AE7: 194 | AF7: 195 | AG7: 196 | AH7: 197 | AI7: 198 | AJ7: 199 | AK7: 200 | AL7: 201 | AM7: 202 | AN7: 203 | AO7: 204 | AP7: 205 | AQ7: 206 | AR7: 207 | AS7: 208 | AT7: 209 | AU7: 210 | AV7: 211 | AW7: 212 | AX7: 213 | AY7: 214 | AZ7: 215 | BA7: 216 | BB7: 217 | BC7: 218 | BD7: 219 | BE7: 220 | BF7: 221 | BG7: 222 | BH7: 223 | BI7: 224 | BJ7: 225 | BK7: 226 | BL7: 227 | BM7: 228 | BN7: 229 | BQ7: Se parte de un punto aproximado y se reemplaza por el centroide de R dentro de un círculo de radio rad_tp; se repite hasta que no se mueve. trackpy además pasa el mapa por un filtro pasa-banda, por eso difiere en ~1–2 px.
B8: 70 | C8: =SUMPRODUCT(INDEX(ImgA,$B8-ImgA_y0+1-25,C$7-ImgA_x0+1-25):INDEX(ImgA,$B8-ImgA_y0+1+25,C$7-ImgA_x0+1+25),Disco)/SUM(Disco) -> 74.167164 | D8: =SUMPRODUCT(INDEX(ImgA,$B8-ImgA_y0+1-25,D$7-ImgA_x0+1-25):INDEX(ImgA,$B8-ImgA_y0+1+25,D$7-ImgA_x0+1+25),Disco)/SUM(Disco) -> 76.677612 | E8: =SUMPRODUCT(INDEX(ImgA,$B8-ImgA_y0+1-25,E$7-ImgA_x0+1-25):INDEX(ImgA,$B8-ImgA_y0+1+25,E$7-ImgA_x0+1+25),Disco)/SUM(Disco) -> 79.319403 | F8: =SUMPRODUCT(INDEX(ImgA,$B8-ImgA_y0+1-25,F$7-ImgA_x0+1-25):INDEX(ImgA,$B8-ImgA_y0+1+25,F$7-ImgA_x0+1+25),Disco)/SUM(Disco) -> 81.916418 | G8: =SUMPRODUCT(INDEX(ImgA,$B8-ImgA_y0+1-25,G$7-ImgA_x0+1-25):INDEX(ImgA,$B8-ImgA_y0+1+25,G$7-ImgA_x0+1+25),Disco)/SUM(Disco) -> 84.475622 | H8: =SUMPRODUCT(INDEX(ImgA,$B8-ImgA_y0+1-25,H$7-ImgA_x0+1-25):INDEX(ImgA,$B8-ImgA_y0+1+25,H$7-ImgA_x0+1+25),Disco)/SUM(Disco) -> 86.710448 | I8: =SUMPRODUCT(INDEX(ImgA,$B8-ImgA_y0+1-25,I$7-ImgA_x0+1-25):INDEX(ImgA,$B8-ImgA_y0+1+25,I$7-ImgA_x0+1+25),Disco)/SUM(Disco) -> 88.526368 | J8: =SUMPRODUCT(INDEX(ImgA,$B8-ImgA_y0+1-25,J$7-ImgA_x0+1-25):INDEX(ImgA,$B8-ImgA_y0+1+25,J$7-ImgA_x0+1+25),Disco)/SUM(Disco) -> 90.314428 | ... BN8: =SUMPRODUCT(INDEX(ImgA,$B8-ImgA_y0+1-25,BN$7-ImgA_x0+1-25):INDEX(ImgA,$B8-ImgA_y0+1+25,BN$7-ImgA_x0+1+25),Disco)/SUM(Disco) -> 84.802985
B9: 71 | C9: =SUMPRODUCT(INDEX(ImgA,$B9-ImgA_y0+1-25,C$7-ImgA_x0+1-25):INDEX(ImgA,$B9-ImgA_y0+1+25,C$7-ImgA_x0+1+25),Disco)/SUM(Disco) -> 76.150249 | D9: =SUMPRODUCT(INDEX(ImgA,$B9-ImgA_y0+1-25,D$7-ImgA_x0+1-25):INDEX(ImgA,$B9-ImgA_y0+1+25,D$7-ImgA_x0+1+25),Disco)/SUM(Disco) -> 78.661692 | E9: =SUMPRODUCT(INDEX(ImgA,$B9-ImgA_y0+1-25,E$7-ImgA_x0+1-25):INDEX(ImgA,$B9-ImgA_y0+1+25,E$7-ImgA_x0+1+25),Disco)/SUM(Disco) -> 81.292537 | F9: =SUMPRODUCT(INDEX(ImgA,$B9-ImgA_y0+1-25,F$7-ImgA_x0+1-25):INDEX(ImgA,$B9-ImgA_y0+1+25,F$7-ImgA_x0+1+25),Disco)/SUM(Disco) -> 83.949254 | G9: =SUMPRODUCT(INDEX(ImgA,$B9-ImgA_y0+1-25,G$7-ImgA_x0+1-25):INDEX(ImgA,$B9-ImgA_y0+1+25,G$7-ImgA_x0+1+25),Disco)/SUM(Disco) -> 86.826866 | H9: =SUMPRODUCT(INDEX(ImgA,$B9-ImgA_y0+1-25,H$7-ImgA_x0+1-25):INDEX(ImgA,$B9-ImgA_y0+1+25,H$7-ImgA_x0+1+25),Disco)/SUM(Disco) -> 89.635821 | I9: =SUMPRODUCT(INDEX(ImgA,$B9-ImgA_y0+1-25,I$7-ImgA_x0+1-25):INDEX(ImgA,$B9-ImgA_y0+1+25,I$7-ImgA_x0+1+25),Disco)/SUM(Disco) -> 91.872637 | J9: =SUMPRODUCT(INDEX(ImgA,$B9-ImgA_y0+1-25,J$7-ImgA_x0+1-25):INDEX(ImgA,$B9-ImgA_y0+1+25,J$7-ImgA_x0+1+25),Disco)/SUM(Disco) -> 93.906468 | ... BN9: =SUMPRODUCT(INDEX(ImgA,$B9-ImgA_y0+1-25,BN$7-ImgA_x0+1-25):INDEX(ImgA,$B9-ImgA_y0+1+25,BN$7-ImgA_x0+1+25),Disco)/SUM(Disco) -> 83.208955 | BR9: Robot 3 x | BS9: Robot 3 y | BT9: Hueco x | BU9: Hueco y
B10: 72 | C10: =SUMPRODUCT(INDEX(ImgA,$B10-ImgA_y0+1-25,C$7-ImgA_x0+1-25):INDEX(ImgA,$B10-ImgA_y0+1+25,C$7-ImgA_x0+1+25),Disco)/SUM(Disco) -> 78.432836 | D10: =SUMPRODUCT(INDEX(ImgA,$B10-ImgA_y0+1-25,D$7-ImgA_x0+1-25):INDEX(ImgA,$B10-ImgA_y0+1+25,D$7-ImgA_x0+1+25),Disco)/SUM(Disco) -> 80.98209 | E10: =SUMPRODUCT(INDEX(ImgA,$B10-ImgA_y0+1-25,E$7-ImgA_x0+1-25):INDEX(ImgA,$B10-ImgA_y0+1+25,E$7-ImgA_x0+1+25),Disco)/SUM(Disco) -> 83.464677 | F10: =SUMPRODUCT(INDEX(ImgA,$B10-ImgA_y0+1-25,F$7-ImgA_x0+1-25):INDEX(ImgA,$B10-ImgA_y0+1+25,F$7-ImgA_x0+1+25),Disco)/SUM(Disco) -> 86.252736 | G10: =SUMPRODUCT(INDEX(ImgA,$B10-ImgA_y0+1-25,G$7-ImgA_x0+1-25):INDEX(ImgA,$B10-ImgA_y0+1+25,G$7-ImgA_x0+1+25),Disco)/SUM(Disco) -> 89.3801 | H10: =SUMPRODUCT(INDEX(ImgA,$B10-ImgA_y0+1-25,H$7-ImgA_x0+1-25):INDEX(ImgA,$B10-ImgA_y0+1+25,H$7-ImgA_x0+1+25),Disco)/SUM(Disco) -> 92.536318 | I10: =SUMPRODUCT(INDEX(ImgA,$B10-ImgA_y0+1-25,I$7-ImgA_x0+1-25):INDEX(ImgA,$B10-ImgA_y0+1+25,I$7-ImgA_x0+1+25),Disco)/SUM(Disco) -> 95.026866 | J10: =SUMPRODUCT(INDEX(ImgA,$B10-ImgA_y0+1-25,J$7-ImgA_x0+1-25):INDEX(ImgA,$B10-ImgA_y0+1+25,J$7-ImgA_x0+1+25),Disco)/SUM(Disco) -> 97.022886 | ... BN10: =SUMPRODUCT(INDEX(ImgA,$B10-ImgA_y0+1-25,BN$7-ImgA_x0+1-25):INDEX(ImgA,$B10-ImgA_y0+1+25,BN$7-ImgA_x0+1+25),Disco)/SUM(Disco) -> 81.78806 | BQ10: punto de partida | BR10: 181 | BS10: 88 | BT10: 214 | BU10: 100
B11: 73 | C11: =SUMPRODUCT(INDEX(ImgA,$B11-ImgA_y0+1-25,C$7-ImgA_x0+1-25):INDEX(ImgA,$B11-ImgA_y0+1+25,C$7-ImgA_x0+1+25),Disco)/SUM(Disco) -> 80.430846 | D11: =SUMPRODUCT(INDEX(ImgA,$B11-ImgA_y0+1-25,D$7-ImgA_x0+1-25):INDEX(ImgA,$B11-ImgA_y0+1+25,D$7-ImgA_x0+1+25),Disco)/SUM(Disco) -> 83.060697 | E11: =SUMPRODUCT(INDEX(ImgA,$B11-ImgA_y0+1-25,E$7-ImgA_x0+1-25):INDEX(ImgA,$B11-ImgA_y0+1+25,E$7-ImgA_x0+1+25),Disco)/SUM(Disco) -> 85.666667 | F11: =SUMPRODUCT(INDEX(ImgA,$B11-ImgA_y0+1-25,F$7-ImgA_x0+1-25):INDEX(ImgA,$B11-ImgA_y0+1+25,F$7-ImgA_x0+1+25),Disco)/SUM(Disco) -> 88.698507 | G11: =SUMPRODUCT(INDEX(ImgA,$B11-ImgA_y0+1-25,G$7-ImgA_x0+1-25):INDEX(ImgA,$B11-ImgA_y0+1+25,G$7-ImgA_x0+1+25),Disco)/SUM(Disco) -> 91.98607 | H11: =SUMPRODUCT(INDEX(ImgA,$B11-ImgA_y0+1-25,H$7-ImgA_x0+1-25):INDEX(ImgA,$B11-ImgA_y0+1+25,H$7-ImgA_x0+1+25),Disco)/SUM(Disco) -> 95.058706 | I11: =SUMPRODUCT(INDEX(ImgA,$B11-ImgA_y0+1-25,I$7-ImgA_x0+1-25):INDEX(ImgA,$B11-ImgA_y0+1+25,I$7-ImgA_x0+1+25),Disco)/SUM(Disco) -> 97.666667 | J11: =SUMPRODUCT(INDEX(ImgA,$B11-ImgA_y0+1-25,J$7-ImgA_x0+1-25):INDEX(ImgA,$B11-ImgA_y0+1+25,J$7-ImgA_x0+1+25),Disco)/SUM(Disco) -> 99.748259 | ... BN11: =SUMPRODUCT(INDEX(ImgA,$B11-ImgA_y0+1-25,BN$7-ImgA_x0+1-25):INDEX(ImgA,$B11-ImgA_y0+1+25,BN$7-ImgA_x0+1+25),Disco)/SUM(Disco) -> 80.595025 | BQ11: iteración 1 | BR11: =SUMPRODUCT(Rmap*(((Xg-ROUND(BR10,0))^2+(Yg-ROUND(BS10,0))^2)<=rad_tp^2)*Xg)/SUMPRODUCT(Rmap*(((Xg-ROUND(BR10,0))^2+(Yg-ROUND(BS10,0))^2)<=rad_tp^2)) -> 179.40139 | BS11: =SUMPRODUCT(Rmap*(((Xg-ROUND(BR10,0))^2+(Yg-ROUND(BS10,0))^2)<=rad_tp^2)*Yg)/SUMPRODUCT(Rmap*(((Xg-ROUND(BR10,0))^2+(Yg-ROUND(BS10,0))^2)<=rad_tp^2)) -> 85.252887 | BT11: =SUMPRODUCT(Rmap*(((Xg-ROUND(BT10,0))^2+(Yg-ROUND(BU10,0))^2)<=rad_tp^2)*Xg)/SUMPRODUCT(Rmap*(((Xg-ROUND(BT10,0))^2+(Yg-ROUND(BU10,0))^2)<=rad_tp^2)) -> 215.42381 | BU11: =SUMPRODUCT(Rmap*(((Xg-ROUND(BT10,0))^2+(Yg-ROUND(BU10,0))^2)<=rad_tp^2)*Yg)/SUMPRODUCT(Rmap*(((Xg-ROUND(BT10,0))^2+(Yg-ROUND(BU10,0))^2)<=rad_tp^2)) -> 99.56004
B12: 74 | C12: =SUMPRODUCT(INDEX(ImgA,$B12-ImgA_y0+1-25,C$7-ImgA_x0+1-25):INDEX(ImgA,$B12-ImgA_y0+1+25,C$7-ImgA_x0+1+25),Disco)/SUM(Disco) -> 82.137313 | D12: =SUMPRODUCT(INDEX(ImgA,$B12-ImgA_y0+1-25,D$7-ImgA_x0+1-25):INDEX(ImgA,$B12-ImgA_y0+1+25,D$7-ImgA_x0+1+25),Disco)/SUM(Disco) -> 85.129353 | E12: =SUMPRODUCT(INDEX(ImgA,$B12-ImgA_y0+1-25,E$7-ImgA_x0+1-25):INDEX(ImgA,$B12-ImgA_y0+1+25,E$7-ImgA_x0+1+25),Disco)/SUM(Disco) -> 88.133333 | F12: =SUMPRODUCT(INDEX(ImgA,$B12-ImgA_y0+1-25,F$7-ImgA_x0+1-25):INDEX(ImgA,$B12-ImgA_y0+1+25,F$7-ImgA_x0+1+25),Disco)/SUM(Disco) -> 91.311443 | G12: =SUMPRODUCT(INDEX(ImgA,$B12-ImgA_y0+1-25,G$7-ImgA_x0+1-25):INDEX(ImgA,$B12-ImgA_y0+1+25,G$7-ImgA_x0+1+25),Disco)/SUM(Disco) -> 94.299502 | H12: =SUMPRODUCT(INDEX(ImgA,$B12-ImgA_y0+1-25,H$7-ImgA_x0+1-25):INDEX(ImgA,$B12-ImgA_y0+1+25,H$7-ImgA_x0+1+25),Disco)/SUM(Disco) -> 97.065672 | I12: =SUMPRODUCT(INDEX(ImgA,$B12-ImgA_y0+1-25,I$7-ImgA_x0+1-25):INDEX(ImgA,$B12-ImgA_y0+1+25,I$7-ImgA_x0+1+25),Disco)/SUM(Disco) -> 99.897512 | J12: =SUMPRODUCT(INDEX(ImgA,$B12-ImgA_y0+1-25,J$7-ImgA_x0+1-25):INDEX(ImgA,$B12-ImgA_y0+1+25,J$7-ImgA_x0+1+25),Disco)/SUM(Disco) -> 102.55423 | ... BN12: =SUMPRODUCT(INDEX(ImgA,$B12-ImgA_y0+1-25,BN$7-ImgA_x0+1-25):INDEX(ImgA,$B12-ImgA_y0+1+25,BN$7-ImgA_x0+1+25),Disco)/SUM(Disco) -> 79.532338 | BQ12: iteración 2 | BR12: =SUMPRODUCT(Rmap*(((Xg-ROUND(BR11,0))^2+(Yg-ROUND(BS11,0))^2)<=rad_tp^2)*Xg)/SUMPRODUCT(Rmap*(((Xg-ROUND(BR11,0))^2+(Yg-ROUND(BS11,0))^2)<=rad_tp^2)) -> 178.64141 | BS12: =SUMPRODUCT(Rmap*(((Xg-ROUND(BR11,0))^2+(Yg-ROUND(BS11,0))^2)<=rad_tp^2)*Yg)/SUMPRODUCT(Rmap*(((Xg-ROUND(BR11,0))^2+(Yg-ROUND(BS11,0))^2)<=rad_tp^2)) -> 83.778387 | BT12: =SUMPRODUCT(Rmap*(((Xg-ROUND(BT11,0))^2+(Yg-ROUND(BU11,0))^2)<=rad_tp^2)*Xg)/SUMPRODUCT(Rmap*(((Xg-ROUND(BT11,0))^2+(Yg-ROUND(BU11,0))^2)<=rad_tp^2)) -> 215.57675 | BU12: =SUMPRODUCT(Rmap*(((Xg-ROUND(BT11,0))^2+(Yg-ROUND(BU11,0))^2)<=rad_tp^2)*Yg)/SUMPRODUCT(Rmap*(((Xg-ROUND(BT11,0))^2+(Yg-ROUND(BU11,0))^2)<=rad_tp^2)) -> 99.685455
B13: 75 | C13: =SUMPRODUCT(INDEX(ImgA,$B13-ImgA_y0+1-25,C$7-ImgA_x0+1-25):INDEX(ImgA,$B13-ImgA_y0+1+25,C$7-ImgA_x0+1+25),Disco)/SUM(Disco) -> 83.688557 | D13: =SUMPRODUCT(INDEX(ImgA,$B13-ImgA_y0+1-25,D$7-ImgA_x0+1-25):INDEX(ImgA,$B13-ImgA_y0+1+25,D$7-ImgA_x0+1+25),Disco)/SUM(Disco) -> 86.884577 | E13: =SUMPRODUCT(INDEX(ImgA,$B13-ImgA_y0+1-25,E$7-ImgA_x0+1-25):INDEX(ImgA,$B13-ImgA_y0+1+25,E$7-ImgA_x0+1+25),Disco)/SUM(Disco) -> 90.143284 | F13: =SUMPRODUCT(INDEX(ImgA,$B13-ImgA_y0+1-25,F$7-ImgA_x0+1-25):INDEX(ImgA,$B13-ImgA_y0+1+25,F$7-ImgA_x0+1+25),Disco)/SUM(Disco) -> 93.175124 | G13: =SUMPRODUCT(INDEX(ImgA,$B13-ImgA_y0+1-25,G$7-ImgA_x0+1-25):INDEX(ImgA,$B13-ImgA_y0+1+25,G$7-ImgA_x0+1+25),Disco)/SUM(Disco) -> 95.973134 | H13: =SUMPRODUCT(INDEX(ImgA,$B13-ImgA_y0+1-25,H$7-ImgA_x0+1-25):INDEX(ImgA,$B13-ImgA_y0+1+25,H$7-ImgA_x0+1+25),Disco)/SUM(Disco) -> 98.652736 | I13: =SUMPRODUCT(INDEX(ImgA,$B13-ImgA_y0+1-25,I$7-ImgA_x0+1-25):INDEX(ImgA,$B13-ImgA_y0+1+25,I$7-ImgA_x0+1+25),Disco)/SUM(Disco) -> 101.81891 | J13: =SUMPRODUCT(INDEX(ImgA,$B13-ImgA_y0+1-25,J$7-ImgA_x0+1-25):INDEX(ImgA,$B13-ImgA_y0+1+25,J$7-ImgA_x0+1+25),Disco)/SUM(Disco) -> 104.74527 | ... BN13: =SUMPRODUCT(INDEX(ImgA,$B13-ImgA_y0+1-25,BN$7-ImgA_x0+1-25):INDEX(ImgA,$B13-ImgA_y0+1+25,BN$7-ImgA_x0+1+25),Disco)/SUM(Disco) -> 78.816915 | BQ13: iteración 3 | BR13: =SUMPRODUCT(Rmap*(((Xg-ROUND(BR12,0))^2+(Yg-ROUND(BS12,0))^2)<=rad_tp^2)*Xg)/SUMPRODUCT(Rmap*(((Xg-ROUND(BR12,0))^2+(Yg-ROUND(BS12,0))^2)<=rad_tp^2)) -> 178.57898 | BS13: =SUMPRODUCT(Rmap*(((Xg-ROUND(BR12,0))^2+(Yg-ROUND(BS12,0))^2)<=rad_tp^2)*Yg)/SUMPRODUCT(Rmap*(((Xg-ROUND(BR12,0))^2+(Yg-ROUND(BS12,0))^2)<=rad_tp^2)) -> 83.345938 | BT13: =SUMPRODUCT(Rmap*(((Xg-ROUND(BT12,0))^2+(Yg-ROUND(BU12,0))^2)<=rad_tp^2)*Xg)/SUMPRODUCT(Rmap*(((Xg-ROUND(BT12,0))^2+(Yg-ROUND(BU12,0))^2)<=rad_tp^2)) -> 215.73876 | BU13: =SUMPRODUCT(Rmap*(((Xg-ROUND(BT12,0))^2+(Yg-ROUND(BU12,0))^2)<=rad_tp^2)*Yg)/SUMPRODUCT(Rmap*(((Xg-ROUND(BT12,0))^2+(Yg-ROUND(BU12,0))^2)<=rad_tp^2)) -> 99.823143
B14: 76 | C14: =SUMPRODUCT(INDEX(ImgA,$B14-ImgA_y0+1-25,C$7-ImgA_x0+1-25):INDEX(ImgA,$B14-ImgA_y0+1+25,C$7-ImgA_x0+1+25),Disco)/SUM(Disco) -> 85.082587 | D14: =SUMPRODUCT(INDEX(ImgA,$B14-ImgA_y0+1-25,D$7-ImgA_x0+1-25):INDEX(ImgA,$B14-ImgA_y0+1+25,D$7-ImgA_x0+1+25),Disco)/SUM(Disco) -> 88.472637 | E14: =SUMPRODUCT(INDEX(ImgA,$B14-ImgA_y0+1-25,E$7-ImgA_x0+1-25):INDEX(ImgA,$B14-ImgA_y0+1+25,E$7-ImgA_x0+1+25),Disco)/SUM(Disco) -> 91.595025 | F14: =SUMPRODUCT(INDEX(ImgA,$B14-ImgA_y0+1-25,F$7-ImgA_x0+1-25):INDEX(ImgA,$B14-ImgA_y0+1+25,F$7-ImgA_x0+1+25),Disco)/SUM(Disco) -> 94.455721 | G14: =SUMPRODUCT(INDEX(ImgA,$B14-ImgA_y0+1-25,G$7-ImgA_x0+1-25):INDEX(ImgA,$B14-ImgA_y0+1+25,G$7-ImgA_x0+1+25),Disco)/SUM(Disco) -> 97.235821 | H14: =SUMPRODUCT(INDEX(ImgA,$B14-ImgA_y0+1-25,H$7-ImgA_x0+1-25):INDEX(ImgA,$B14-ImgA_y0+1+25,H$7-ImgA_x0+1+25),Disco)/SUM(Disco) -> 100.26468 | I14: =SUMPRODUCT(INDEX(ImgA,$B14-ImgA_y0+1-25,I$7-ImgA_x0+1-25):INDEX(ImgA,$B14-ImgA_y0+1+25,I$7-ImgA_x0+1+25),Disco)/SUM(Disco) -> 103.51642 | J14: =SUMPRODUCT(INDEX(ImgA,$B14-ImgA_y0+1-25,J$7-ImgA_x0+1-25):INDEX(ImgA,$B14-ImgA_y0+1+25,J$7-ImgA_x0+1+25),Disco)/SUM(Disco) -> 106.28259 | ... BN14: =SUMPRODUCT(INDEX(ImgA,$B14-ImgA_y0+1-25,BN$7-ImgA_x0+1-25):INDEX(ImgA,$B14-ImgA_y0+1+25,BN$7-ImgA_x0+1+25),Disco)/SUM(Disco) -> 78.344279 | BQ14: iteración 4 | BR14: =SUMPRODUCT(Rmap*(((Xg-ROUND(BR13,0))^2+(Yg-ROUND(BS13,0))^2)<=rad_tp^2)*Xg)/SUMPRODUCT(Rmap*(((Xg-ROUND(BR13,0))^2+(Yg-ROUND(BS13,0))^2)<=rad_tp^2)) -> 178.53575 | BS14: =SUMPRODUCT(Rmap*(((Xg-ROUND(BR13,0))^2+(Yg-ROUND(BS13,0))^2)<=rad_tp^2)*Yg)/SUMPRODUCT(Rmap*(((Xg-ROUND(BR13,0))^2+(Yg-ROUND(BS13,0))^2)<=rad_tp^2)) -> 82.897803 | BT14: =SUMPRODUCT(Rmap*(((Xg-ROUND(BT13,0))^2+(Yg-ROUND(BU13,0))^2)<=rad_tp^2)*Xg)/SUMPRODUCT(Rmap*(((Xg-ROUND(BT13,0))^2+(Yg-ROUND(BU13,0))^2)<=rad_tp^2)) -> 215.73876 | BU14: =SUMPRODUCT(Rmap*(((Xg-ROUND(BT13,0))^2+(Yg-ROUND(BU13,0))^2)<=rad_tp^2)*Yg)/SUMPRODUCT(Rmap*(((Xg-ROUND(BT13,0))^2+(Yg-ROUND(BU13,0))^2)<=rad_tp^2)) -> 99.823143
B15: 77 | C15: =SUMPRODUCT(INDEX(ImgA,$B15-ImgA_y0+1-25,C$7-ImgA_x0+1-25):INDEX(ImgA,$B15-ImgA_y0+1+25,C$7-ImgA_x0+1+25),Disco)/SUM(Disco) -> 86.725373 | D15: =SUMPRODUCT(INDEX(ImgA,$B15-ImgA_y0+1-25,D$7-ImgA_x0+1-25):INDEX(ImgA,$B15-ImgA_y0+1+25,D$7-ImgA_x0+1+25),Disco)/SUM(Disco) -> 90.134328 | E15: =SUMPRODUCT(INDEX(ImgA,$B15-ImgA_y0+1-25,E$7-ImgA_x0+1-25):INDEX(ImgA,$B15-ImgA_y0+1+25,E$7-ImgA_x0+1+25),Disco)/SUM(Disco) -> 92.946269 | F15: =SUMPRODUCT(INDEX(ImgA,$B15-ImgA_y0+1-25,F$7-ImgA_x0+1-25):INDEX(ImgA,$B15-ImgA_y0+1+25,F$7-ImgA_x0+1+25),Disco)/SUM(Disco) -> 95.766169 | G15: =SUMPRODUCT(INDEX(ImgA,$B15-ImgA_y0+1-25,G$7-ImgA_x0+1-25):INDEX(ImgA,$B15-ImgA_y0+1+25,G$7-ImgA_x0+1+25),Disco)/SUM(Disco) -> 98.752239 | H15: =SUMPRODUCT(INDEX(ImgA,$B15-ImgA_y0+1-25,H$7-ImgA_x0+1-25):INDEX(ImgA,$B15-ImgA_y0+1+25,H$7-ImgA_x0+1+25),Disco)/SUM(Disco) -> 101.98507 | I15: =SUMPRODUCT(INDEX(ImgA,$B15-ImgA_y0+1-25,I$7-ImgA_x0+1-25):INDEX(ImgA,$B15-ImgA_y0+1+25,I$7-ImgA_x0+1+25),Disco)/SUM(Disco) -> 105.12537 | J15: =SUMPRODUCT(INDEX(ImgA,$B15-ImgA_y0+1-25,J$7-ImgA_x0+1-25):INDEX(ImgA,$B15-ImgA_y0+1+25,J$7-ImgA_x0+1+25),Disco)/SUM(Disco) -> 107.64378 | ... BN15: =SUMPRODUCT(INDEX(ImgA,$B15-ImgA_y0+1-25,BN$7-ImgA_x0+1-25):INDEX(ImgA,$B15-ImgA_y0+1+25,BN$7-ImgA_x0+1+25),Disco)/SUM(Disco) -> 78.654726 | BQ15: iteración 5 | BR15: =SUMPRODUCT(Rmap*(((Xg-ROUND(BR14,0))^2+(Yg-ROUND(BS14,0))^2)<=rad_tp^2)*Xg)/SUMPRODUCT(Rmap*(((Xg-ROUND(BR14,0))^2+(Yg-ROUND(BS14,0))^2)<=rad_tp^2)) -> 178.53575 | BS15: =SUMPRODUCT(Rmap*(((Xg-ROUND(BR14,0))^2+(Yg-ROUND(BS14,0))^2)<=rad_tp^2)*Yg)/SUMPRODUCT(Rmap*(((Xg-ROUND(BR14,0))^2+(Yg-ROUND(BS14,0))^2)<=rad_tp^2)) -> 82.897803 | BT15: =SUMPRODUCT(Rmap*(((Xg-ROUND(BT14,0))^2+(Yg-ROUND(BU14,0))^2)<=rad_tp^2)*Xg)/SUMPRODUCT(Rmap*(((Xg-ROUND(BT14,0))^2+(Yg-ROUND(BU14,0))^2)<=rad_tp^2)) -> 215.73876 | BU15: =SUMPRODUCT(Rmap*(((Xg-ROUND(BT14,0))^2+(Yg-ROUND(BU14,0))^2)<=rad_tp^2)*Yg)/SUMPRODUCT(Rmap*(((Xg-ROUND(BT14,0))^2+(Yg-ROUND(BU14,0))^2)<=rad_tp^2)) -> 99.823143
B16: 78 | C16: =SUMPRODUCT(INDEX(ImgA,$B16-ImgA_y0+1-25,C$7-ImgA_x0+1-25):INDEX(ImgA,$B16-ImgA_y0+1+25,C$7-ImgA_x0+1+25),Disco)/SUM(Disco) -> 88.098507 | D16: =SUMPRODUCT(INDEX(ImgA,$B16-ImgA_y0+1-25,D$7-ImgA_x0+1-25):INDEX(ImgA,$B16-ImgA_y0+1+25,D$7-ImgA_x0+1+25),Disco)/SUM(Disco) -> 91.463682 | E16: =SUMPRODUCT(INDEX(ImgA,$B16-ImgA_y0+1-25,E$7-ImgA_x0+1-25):INDEX(ImgA,$B16-ImgA_y0+1+25,E$7-ImgA_x0+1+25),Disco)/SUM(Disco) -> 94.247761 | F16: =SUMPRODUCT(INDEX(ImgA,$B16-ImgA_y0+1-25,F$7-ImgA_x0+1-25):INDEX(ImgA,$B16-ImgA_y0+1+25,F$7-ImgA_x0+1+25),Disco)/SUM(Disco) -> 97.130348 | G16: =SUMPRODUCT(INDEX(ImgA,$B16-ImgA_y0+1-25,G$7-ImgA_x0+1-25):INDEX(ImgA,$B16-ImgA_y0+1+25,G$7-ImgA_x0+1+25),Disco)/SUM(Disco) -> 100.48159 | H16: =SUMPRODUCT(INDEX(ImgA,$B16-ImgA_y0+1-25,H$7-ImgA_x0+1-25):INDEX(ImgA,$B16-ImgA_y0+1+25,H$7-ImgA_x0+1+25),Disco)/SUM(Disco) -> 103.85174 | I16: =SUMPRODUCT(INDEX(ImgA,$B16-ImgA_y0+1-25,I$7-ImgA_x0+1-25):INDEX(ImgA,$B16-ImgA_y0+1+25,I$7-ImgA_x0+1+25),Disco)/SUM(Disco) -> 106.76816 | J16: =SUMPRODUCT(INDEX(ImgA,$B16-ImgA_y0+1-25,J$7-ImgA_x0+1-25):INDEX(ImgA,$B16-ImgA_y0+1+25,J$7-ImgA_x0+1+25),Disco)/SUM(Disco) -> 109.17413 | ... BN16: =SUMPRODUCT(INDEX(ImgA,$B16-ImgA_y0+1-25,BN$7-ImgA_x0+1-25):INDEX(ImgA,$B16-ImgA_y0+1+25,BN$7-ImgA_x0+1+25),Disco)/SUM(Disco) -> 79.700498 | BQ16: iteración 6 | BR16: =SUMPRODUCT(Rmap*(((Xg-ROUND(BR15,0))^2+(Yg-ROUND(BS15,0))^2)<=rad_tp^2)*Xg)/SUMPRODUCT(Rmap*(((Xg-ROUND(BR15,0))^2+(Yg-ROUND(BS15,0))^2)<=rad_tp^2)) -> 178.53575 | BS16: =SUMPRODUCT(Rmap*(((Xg-ROUND(BR15,0))^2+(Yg-ROUND(BS15,0))^2)<=rad_tp^2)*Yg)/SUMPRODUCT(Rmap*(((Xg-ROUND(BR15,0))^2+(Yg-ROUND(BS15,0))^2)<=rad_tp^2)) -> 82.897803 | BT16: =SUMPRODUCT(Rmap*(((Xg-ROUND(BT15,0))^2+(Yg-ROUND(BU15,0))^2)<=rad_tp^2)*Xg)/SUMPRODUCT(Rmap*(((Xg-ROUND(BT15,0))^2+(Yg-ROUND(BU15,0))^2)<=rad_tp^2)) -> 215.73876 | BU16: =SUMPRODUCT(Rmap*(((Xg-ROUND(BT15,0))^2+(Yg-ROUND(BU15,0))^2)<=rad_tp^2)*Yg)/SUMPRODUCT(Rmap*(((Xg-ROUND(BT15,0))^2+(Yg-ROUND(BU15,0))^2)<=rad_tp^2)) -> 99.823143
