Workbook

Sheet Notas
A1: Metodologia de calculo
A4: 1) G (conductancia, uS)
A5: G = ADC_RAW * K_G_US, con K_G_US = (V_REF * 1e6) / (ADC_FS * V_EXC * R_FEEDBACK).
A6: Formula del front-end de Codigo/fsr_single_read/fsr_single_read.ino. Ver hoja Config (fila 6) y columna D de la hoja Datos.
A8: 2) deltaG (el 'diferencial') y deltaT
A9: deltaT es el tamano de ventana temporal, en segundos: se barre de forma continua
A10: de STEP_S (50 ms) a DELTA_MAX_S (15 s), en pasos de 50 ms (300 valores).
A11: Para cada deltaT: deltaG(t) = G(t) - G(t - deltaT), calculado sobre N_VENTANA = 1200 puntos fijos (para que todos los deltaT, incluido el maximo de 15 s = 300
A12: muestras de lag, quepan dentro de los 1500 puntos cargados). Ver hoja Ejemplo_ventana para el detalle fila por fila de un deltaT elegido a mano.
A14: 3) Skewness (asimetria) y kurtosis
A15: Para cada deltaT, se toma toda la distribucion de deltaG(t) (los 1200 puntos) y se
A16: le aplican las funciones nativas de Excel SKEW() y KURT() -- formulas matriciales
... A39: calculos en Python sobre los ~36000 puntos de cada medicion completa.

Sheet Config
A1: Configuracion y calibracion del front-end FSR
A3: Parametro | B3: Valor | C3: Unidad | D3: Descripcion
A4: V_REF | B4: 3.3 | C4: V | D4: Tension de referencia del ADC
A5: V_EXC | B5: 0.7534 | C5: V | D5: Tension de excitacion
A6: R_FEEDBACK | B6: 12000 | C6: ohm | D6: Resistencia de realimentacion
A7: ADC_FS | B7: 1023 | C7: - | D7: Escala completa del ADC (10 bits)
A8: K_G_US | B8: =(B4*1000000)/(B7*B5*B6) -> 0.35680542 | C8: uS/cuenta | D8: G = ADC_RAW * K_G_US (formula en hoja Datos)
A9: STEP_S | B9: 0.05 | C9: s | D9: Paso de muestreo y de barrido de deltaT
A10: DELTA_MAX_S | B10: 15 | C10: s | D10: Mayor tamano de ventana barrido
A11: N_MUESTRAS | B11: =COUNT(Datos!$A$2:$A$1501) -> 1500 | C11: - | D11: Cantidad de filas de datos cargadas
A12: N_VENTANA | B12: 1200 | C12: - | D12: Cant. de puntos fijos usados en cada calculo de skewness/kurtosis (ver Notas)
A14: Ver hoja 'Notas' para la explicacion completa de la metodologia.

Sheet Datos
A1: timestamp_original_s | B1: tiempo | C1: ADC_RAW | D1: G | F1: Nota
A2: 2025.881 | B2: =A2-$A$2 -> 0 | C2: 443.59 | D2: =C2*Config!$B$8 -> 158.27532 | F2: Se usan los tiempos crudos del log (ya muestreados a ~50 ms por el firmware) sin remuestrear a grilla uniforme por interpolacion, a diferencia del script Python (procesar_presion_ventanas.py), que si interpola. Simplificacion para que las formulas de Excel sean legibles.
A3: 2025.931 | B3: =A3-$A$2 -> 0.05 | C3: 437.63 | D3: =C3*Config!$B$8 -> 156.14876
A4: 2025.981 | B4: =A4-$A$2 -> 0.1 | C4: 438.3 | D4: =C4*Config!$B$8 -> 156.38782
A5: 2026.031 | B5: =A5-$A$2 -> 0.15 | C5: 432.64 | D5: =C5*Config!$B$8 -> 154.3683
A6: 2026.081 | B6: =A6-$A$2 -> 0.2 | C6: 442.92 | D6: =C6*Config!$B$8 -> 158.03626
A7: 2026.131 | B7: =A7-$A$2 -> 0.25 | C7: 437.54 | D7: =C7*Config!$B$8 -> 156.11664
A8: 2026.181 | B8: =A8-$A$2 -> 0.3 | C8: 444.38 | D8: =C8*Config!$B$8 -> 158.55719
A9: 2026.231 | B9: =A9-$A$2 -> 0.35 | C9: 443.57 | D9: =C9*Config!$B$8 -> 158.26818
A10: 2026.281 | B10: =A10-$A$2 -> 0.4 | C10: 433.27 | D10: =C10*Config!$B$8 -> 154.59308
A11: 2026.331 | B11: =A11-$A$2 -> 0.45 | C11: 446.75 | D11: =C11*Config!$B$8 -> 159.40282
A12: 2026.381 | B12: =A12-$A$2 -> 0.5 | C12: 434.65 | D12: =C12*Config!$B$8 -> 155.08548
A13: 2026.431 | B13: =A13-$A$2 -> 0.55 | C13: 452.05 | D13: =C13*Config!$B$8 -> 161.29389
A14: 2026.481 | B14: =A14-$A$2 -> 0.6 | C14: 440.71 | D14: =C14*Config!$B$8 -> 157.24772
... A1501: 2100.866 | B1501: =A1501-$A$2 -> 74.985 | C1501: 423.75 | D1501: =C1501*Config!$B$8 -> 151.1963

Sheet Ejemplo_ventana
A1: Ejemplo de calculo para un deltaT elegido
A3: deltaT (s) -- EDITAR ESTA CELDA | B3: 2.5
A4: lag (muestras) = deltaT / STEP_S | B4: =ROUND(B3/Config!$B$9,0) -> 50
A6: Skewness (Excel SKEW, sobre N_VENTANA puntos) | B6: {=SKEW(OFFSET(Datos!$D$1,1+$B$4,0,Config!$B$12,1)-OFFSET(Datos!$D$1,1,0,Config!$B$12,1))} -> 0.28626694
A7: Kurtosis (Excel KURT, exceso; Normal=0) | B7: {=KURT(OFFSET(Datos!$D$1,1+$B$4,0,Config!$B$12,1)-OFFSET(Datos!$D$1,1,0,Config!$B$12,1))} -> 0.1975872
A9: Cambiando B3 (deltaT, entre 0.05 y 15 s) se recalculan B4, B6 y B7, y toda la columna de deltaG de abajo, en vivo.
A11: fila i | B11: tiempo (t) | C11: G(t) | D11: G(t - deltaT) | E11: deltaG = G(t) - G(t-deltaT)
A12: 1 | B12: =OFFSET(Datos!$B$1,1+$B$4+0,0) -> 2.501 | C12: =OFFSET(Datos!$D$1,1+$B$4+0,0) -> 155.25317 | D12: =OFFSET(Datos!$D$1,1+0,0) -> 158.27532 | E12: =C12-D12 -> -3.0221419
A13: 2 | B13: =OFFSET(Datos!$B$1,1+$B$4+1,0) -> 2.551 | C13: =OFFSET(Datos!$D$1,1+$B$4+1,0) -> 153.49412 | D13: =OFFSET(Datos!$D$1,1+1,0) -> 156.14876 | E13: =C13-D13 -> -2.6546323
A14: 3 | B14: =OFFSET(Datos!$B$1,1+$B$4+2,0) -> 2.601 | C14: =OFFSET(Datos!$D$1,1+$B$4+2,0) -> 155.02482 | D14: =OFFSET(Datos!$D$1,1+2,0) -> 156.38782 | E14: =C14-D14 -> -1.3629967
A15: 4 | B15: =OFFSET(Datos!$B$1,1+$B$4+3,0) -> 2.651 | C15: =OFFSET(Datos!$D$1,1+$B$4+3,0) -> 154.64661 | D15: =OFFSET(Datos!$D$1,1+3,0) -> 154.3683 | E15: =C15-D15 -> 0.27830823
A16: 5 | B16: =OFFSET(Datos!$B$1,1+$B$4+4,0) -> 2.701 | C16: =OFFSET(Datos!$D$1,1+$B$4+4,0) -> 152.94108 | D16: =OFFSET(Datos!$D$1,1+4,0) -> 158.03626 | E16: =C16-D16 -> -5.0951814
A17: 6 | B17: =OFFSET(Datos!$B$1,1+$B$4+5,0) -> 2.751 | C17: =OFFSET(Datos!$D$1,1+$B$4+5,0) -> 153.84379 | D17: =OFFSET(Datos!$D$1,1+5,0) -> 156.11664 | E17: =C17-D17 -> -2.2728505
A18: 7 | B18: =OFFSET(Datos!$B$1,1+$B$4+6,0) -> 2.801 | C18: =OFFSET(Datos!$D$1,1+$B$4+6,0) -> 155.139 | D18: =OFFSET(Datos!$D$1,1+6,0) -> 158.55719 | E18: =C18-D18 -> -3.4181959
A19: 8 | B19: =OFFSET(Datos!$B$1,1+$B$4+7,0) -> 2.851 | C19: =OFFSET(Datos!$D$1,1+$B$4+7,0) -> 153.80098 | D19: =OFFSET(Datos!$D$1,1+7,0) -> 158.26818 | E19: =C19-D19 -> -4.4672039
A20: 9 | B20: =OFFSET(Datos!$B$1,1+$B$4+8,0) -> 2.901 | C20: =OFFSET(Datos!$D$1,1+$B$4+8,0) -> 154.9713 | D20: =OFFSET(Datos!$D$1,1+8,0) -> 154.59308 | E20: =C20-D20 -> 0.37821375
A21: 10 | B21: =OFFSET(Datos!$B$1,1+$B$4+9,0) -> 2.951 | C21: =OFFSET(Datos!$D$1,1+$B$4+9,0) -> 154.77862 | D21: =OFFSET(Datos!$D$1,1+9,0) -> 159.40282 | E21: =C21-D21 -> -4.6241983
A22: 11 | B22: =OFFSET(Datos!$B$1,1+$B$4+10,0) -> 3.001 | C22: =OFFSET(Datos!$D$1,1+$B$4+10,0) -> 154.94989 | D22: =OFFSET(Datos!$D$1,1+10,0) -> 155.08548 | E22: =C22-D22 -> -0.13558606
A23: 12 | B23: =OFFSET(Datos!$B$1,1+$B$4+11,0) -> 3.051 | C23: =OFFSET(Datos!$D$1,1+$B$4+11,0) -> 155.71702 | D23: =OFFSET(Datos!$D$1,1+11,0) -> 161.29389 | E23: =C23-D23 -> -5.5768687
A24: 13 | B24: =OFFSET(Datos!$B$1,1+$B$4+12,0) -> 3.101 | C24: =OFFSET(Datos!$D$1,1+$B$4+12,0) -> 154.17562 | D24: =OFFSET(Datos!$D$1,1+12,0) -> 157.24772 | E24: =C24-D24 -> -3.0720947
A25: 14 | B25: =OFFSET(Datos!$B$1,1+$B$4+13,0) -> 3.151 | C25: =OFFSET(Datos!$D$1,1+$B$4+13,0) -> 153.89018 | D25: =OFFSET(Datos!$D$1,1+13,0) -> 154.55384 | E25: =C25-D25 -> -0.66365808
A26: 15 | B26: =OFFSET(Datos!$B$1,1+$B$4+14,0) -> 3.201 | C26: =OFFSET(Datos!$D$1,1+$B$4+14,0) -> 151.73507 | D26: =OFFSET(Datos!$D$1,1+14,0) -> 159.55268 | E26: =C26-D26 -> -7.8176068
A27: 16 | B27: =OFFSET(Datos!$B$1,1+$B$4+15,0) -> 3.251 | C27: =OFFSET(Datos!$D$1,1+$B$4+15,0) -> 153.24793 | D27: =OFFSET(Datos!$D$1,1+15,0) -> 157.45466 | E27: =C27-D27 -> -4.2067359
A28: 17 | B28: =OFFSET(Datos!$B$1,1+$B$4+16,0) -> 3.301 | C28: =OFFSET(Datos!$D$1,1+$B$4+16,0) -> 153.75816 | D28: =OFFSET(Datos!$D$1,1+16,0) -> 158.57503 | E28: =C28-D28 -> -4.8168732
A29: 18 | B29: =OFFSET(Datos!$B$1,1+$B$4+17,0) -> 3.351 | C29: =OFFSET(Datos!$D$1,1+$B$4+17,0) -> 154.77149 | D29: =OFFSET(Datos!$D$1,1+17,0) -> 156.34143 | E29: =C29-D29 -> -1.5699439
A30: 19 | B30: =OFFSET(Datos!$B$1,1+$B$4+18,0) -> 3.401 | C30: =OFFSET(Datos!$D$1,1+$B$4+18,0) -> 152.95892 | D30: =OFFSET(Datos!$D$1,1+18,0) -> 159.2708 | E30: =C30-D30 -> -6.3118879
A31: 20 | B31: =OFFSET(Datos!$B$1,1+$B$4+19,0) -> 3.451 | C31: =OFFSET(Datos!$D$1,1+$B$4+19,0) -> 152.48436 | D31: =OFFSET(Datos!$D$1,1+19,0) -> 155.28886 | E31: =C31-D31 -> -2.8044906
A32: 21 | B32: =OFFSET(Datos!$B$1,1+$B$4+20,0) -> 3.501 | C32: =OFFSET(Datos!$D$1,1+$B$4+20,0) -> 152.35235 | D32: =OFFSET(Datos!$D$1,1+20,0) -> 156.39138 | E32: =C32-D32 -> -4.0390374
A33: 22 | B33: =OFFSET(Datos!$B$1,1+$B$4+21,0) -> 3.551 | C33: =OFFSET(Datos!$D$1,1+$B$4+21,0) -> 152.69488 | D33: =OFFSET(Datos!$D$1,1+21,0) -> 157.14068 | E33: =C33-D33 -> -4.4457955
A34: 23 | B34: =OFFSET(Datos!$B$1,1+$B$4+22,0) -> 3.602 | C34: =OFFSET(Datos!$D$1,1+$B$4+22,0) -> 153.33356 | D34: =OFFSET(Datos!$D$1,1+22,0) -> 155.90613 | E34: =C34-D34 -> -2.5725671
A35: 24 | B35: =OFFSET(Datos!$B$1,1+$B$4+23,0) -> 3.652 | C35: =OFFSET(Datos!$D$1,1+$B$4+23,0) -> 154.85712 | D35: =OFFSET(Datos!$D$1,1+23,0) -> 156.01674 | E35: =C35-D35 -> -1.1596176
A36: 25 | B36: =OFFSET(Datos!$B$1,1+$B$4+24,0) -> 3.702 | C36: =OFFSET(Datos!$D$1,1+$B$4+24,0) -> 152.73056 | D36: =OFFSET(Datos!$D$1,1+24,0) -> 157.63664 | E36: =C36-D36 -> -4.9060745
A37: 26 | B37: =OFFSET(Datos!$B$1,1+$B$4+25,0) -> 3.752 | C37: =OFFSET(Datos!$D$1,1+$B$4+25,0) -> 152.91967 | D37: =OFFSET(Datos!$D$1,1+25,0) -> 156.86237 | E37: =C37-D37 -> -3.9426999
A38: 27 | B38: =OFFSET(Datos!$B$1,1+$B$4+26,0) -> 3.802 | C38: =OFFSET(Datos!$D$1,1+$B$4+26,0) -> 152.09901 | D38: =OFFSET(Datos!$D$1,1+26,0) -> 157.35476 | E38: =C38-D38 -> -5.2557439
A39: 28 | B39: =OFFSET(Datos!$B$1,1+$B$4+27,0) -> 3.852 | C39: =OFFSET(Datos!$D$1,1+$B$4+27,0) -> 153.44774 | D39: =OFFSET(Datos!$D$1,1+27,0) -> 159.35644 | E39: =C39-D39 -> -5.9086978
A40: 29 | B40: =OFFSET(Datos!$B$1,1+$B$4+28,0) -> 3.902 | C40: =OFFSET(Datos!$D$1,1+$B$4+28,0) -> 153.75102 | D40: =OFFSET(Datos!$D$1,1+28,0) -> 155.53148 | E40: =C40-D40 -> -1.7804591
A41: 30 | B41: =OFFSET(Datos!$B$1,1+$B$4+29,0) -> 3.952 | C41: =OFFSET(Datos!$D$1,1+$B$4+29,0) -> 151.52456 | D41: =OFFSET(Datos!$D$1,1+29,0) -> 156.5127 | E41: =C41-D41 -> -4.9881398
A42: 31 | B42: =OFFSET(Datos!$B$1,1+$B$4+30,0) -> 4.002 | C42: =OFFSET(Datos!$D$1,1+$B$4+30,0) -> 152.74483 | D42: =OFFSET(Datos!$D$1,1+30,0) -> 159.94517 | E42: =C42-D42 -> -7.2003334
A43: 32 | B43: =OFFSET(Datos!$B$1,1+$B$4+31,0) -> 4.052 | C43: =OFFSET(Datos!$D$1,1+$B$4+31,0) -> 153.65469 | D43: =OFFSET(Datos!$D$1,1+31,0) -> 154.13994 | E43: =C43-D43 -> -0.48525537
A44: 33 | B44: =OFFSET(Datos!$B$1,1+$B$4+32,0) -> 4.102 | C44: =OFFSET(Datos!$D$1,1+$B$4+32,0) -> 152.90183 | D44: =OFFSET(Datos!$D$1,1+32,0) -> 153.37281 | E44: =C44-D44 -> -0.47098316
...

Sheet Barrido_deltaT
A1: Asimetria (skewness) y curtosis totales en funcion de deltaT
A2: Cada fila barre un deltaT distinto (50 ms a 15 s, paso 50 ms). Para cada uno, deltaG(t) = G(t) - G(t-deltaT) se arma sobre N_VENTANA puntos fijos y SKEW()/KURT() se calculan sobre esa distribucion completa (formula matricial, recalcula solo si se edita Config o Datos).
A4: lag (muestras) | B4: deltaT (s) | C4: skewness | D4: kurtosis (exceso)
A5: 1 | B5: =A5*Config!$B$9 -> 0.05 | C5: {=SKEW(OFFSET(Datos!$D$1,1+A5,0,Config!$B$12,1)-OFFSET(Datos!$D$1,1,0,Config!$B$12,1))} -> -0.22522126 | D5: {=KURT(OFFSET(Datos!$D$1,1+A5,0,Config!$B$12,1)-OFFSET(Datos!$D$1,1,0,Config!$B$12,1))} -> 1.3748027
A6: 2 | B6: =A6*Config!$B$9 -> 0.1 | C6: {=SKEW(OFFSET(Datos!$D$1,1+A6,0,Config!$B$12,1)-OFFSET(Datos!$D$1,1,0,Config!$B$12,1))} -> -0.037358417 | D6: {=KURT(OFFSET(Datos!$D$1,1+A6,0,Config!$B$12,1)-OFFSET(Datos!$D$1,1,0,Config!$B$12,1))} -> 1.0436422
A7: 3 | B7: =A7*Config!$B$9 -> 0.15 | C7: {=SKEW(OFFSET(Datos!$D$1,1+A7,0,Config!$B$12,1)-OFFSET(Datos!$D$1,1,0,Config!$B$12,1))} -> 0.058475402 | D7: {=KURT(OFFSET(Datos!$D$1,1+A7,0,Config!$B$12,1)-OFFSET(Datos!$D$1,1,0,Config!$B$12,1))} -> 0.78635934
A8: 4 | B8: =A8*Config!$B$9 -> 0.2 | C8: {=SKEW(OFFSET(Datos!$D$1,1+A8,0,Config!$B$12,1)-OFFSET(Datos!$D$1,1,0,Config!$B$12,1))} -> -0.13648479 | D8: {=KURT(OFFSET(Datos!$D$1,1+A8,0,Config!$B$12,1)-OFFSET(Datos!$D$1,1,0,Config!$B$12,1))} -> 1.0794377
A9: 5 | B9: =A9*Config!$B$9 -> 0.25 | C9: {=SKEW(OFFSET(Datos!$D$1,1+A9,0,Config!$B$12,1)-OFFSET(Datos!$D$1,1,0,Config!$B$12,1))} -> -0.0032788325 | D9: {=KURT(OFFSET(Datos!$D$1,1+A9,0,Config!$B$12,1)-OFFSET(Datos!$D$1,1,0,Config!$B$12,1))} -> 0.8125789
A10: 6 | B10: =A10*Config!$B$9 -> 0.3 | C10: {=SKEW(OFFSET(Datos!$D$1,1+A10,0,Config!$B$12,1)-OFFSET(Datos!$D$1,1,0,Config!$B$12,1))} -> -0.047634239 | D10: {=KURT(OFFSET(Datos!$D$1,1+A10,0,Config!$B$12,1)-OFFSET(Datos!$D$1,1,0,Config!$B$12,1))} -> 1.2666439
A11: 7 | B11: =A11*Config!$B$9 -> 0.35 | C11: {=SKEW(OFFSET(Datos!$D$1,1+A11,0,Config!$B$12,1)-OFFSET(Datos!$D$1,1,0,Config!$B$12,1))} -> -0.075157141 | D11: {=KURT(OFFSET(Datos!$D$1,1+A11,0,Config!$B$12,1)-OFFSET(Datos!$D$1,1,0,Config!$B$12,1))} -> 0.69957648
A12: 8 | B12: =A12*Config!$B$9 -> 0.4 | C12: {=SKEW(OFFSET(Datos!$D$1,1+A12,0,Config!$B$12,1)-OFFSET(Datos!$D$1,1,0,Config!$B$12,1))} -> 0.094931142 | D12: {=KURT(OFFSET(Datos!$D$1,1+A12,0,Config!$B$12,1)-OFFSET(Datos!$D$1,1,0,Config!$B$12,1))} -> 0.54580865
A13: 9 | B13: =A13*Config!$B$9 -> 0.45 | C13: {=SKEW(OFFSET(Datos!$D$1,1+A13,0,Config!$B$12,1)-OFFSET(Datos!$D$1,1,0,Config!$B$12,1))} -> 0.096761402 | D13: {=KURT(OFFSET(Datos!$D$1,1+A13,0,Config!$B$12,1)-OFFSET(Datos!$D$1,1,0,Config!$B$12,1))} -> 0.77731918
A14: 10 | B14: =A14*Config!$B$9 -> 0.5 | C14: {=SKEW(OFFSET(Datos!$D$1,1+A14,0,Config!$B$12,1)-OFFSET(Datos!$D$1,1,0,Config!$B$12,1))} -> 0.002402082 | D14: {=KURT(OFFSET(Datos!$D$1,1+A14,0,Config!$B$12,1)-OFFSET(Datos!$D$1,1,0,Config!$B$12,1))} -> 1.1455369
A15: 11 | B15: =A15*Config!$B$9 -> 0.55 | C15: {=SKEW(OFFSET(Datos!$D$1,1+A15,0,Config!$B$12,1)-OFFSET(Datos!$D$1,1,0,Config!$B$12,1))} -> 0.083930555 | D15: {=KURT(OFFSET(Datos!$D$1,1+A15,0,Config!$B$12,1)-OFFSET(Datos!$D$1,1,0,Config!$B$12,1))} -> 0.92274005
A16: 12 | B16: =A16*Config!$B$9 -> 0.6 | C16: {=SKEW(OFFSET(Datos!$D$1,1+A16,0,Config!$B$12,1)-OFFSET(Datos!$D$1,1,0,Config!$B$12,1))} -> 0.11832594 | D16: {=KURT(OFFSET(Datos!$D$1,1+A16,0,Config!$B$12,1)-OFFSET(Datos!$D$1,1,0,Config!$B$12,1))} -> 0.94270958
... A304: 300 | B304: =A304*Config!$B$9 -> 15 | C304: {=SKEW(OFFSET(Datos!$D$1,1+A304,0,Config!$B$12,1)-OFFSET(Datos!$D$1,1,0,Config!$B$12,1))} -> 0.14662324 | D304: {=KURT(OFFSET(Datos!$D$1,1+A304,0,Config!$B$12,1)-OFFSET(Datos!$D$1,1,0,Config!$B$12,1))} -> -0.50814488

Sheet Supervivencia
A1: Funcion de supervivencia de G: P(G >= g)
A2: G_ordenado(k) = SMALL(Datos!G, k) -- el k-esimo valor mas chico de G. P_G_geq(k) = (N - k + 1) / N -- fraccion de las N muestras que son >= a ese G. Graficar G_ordenado (eje X) vs. P_G_geq (eje Y, escala log) reproduce la figura de referencia P(f>=F).
A4: k | B4: G_ordenado | C4: P_G_geq
A5: 1 | B5: =SMALL(Datos!$D$2:$D$1501,A5) -> 144.71314 | C5: =(Config!$B$11-A5+1)/Config!$B$11 -> 1
A6: 2 | B6: =SMALL(Datos!$D$2:$D$1501,A6) -> 145.51595 | C6: =(Config!$B$11-A6+1)/Config!$B$11 -> 0.99933333
A7: 3 | B7: =SMALL(Datos!$D$2:$D$1501,A7) -> 145.55164 | C7: =(Config!$B$11-A7+1)/Config!$B$11 -> 0.99866667
A8: 4 | B8: =SMALL(Datos!$D$2:$D$1501,A8) -> 145.87633 | C8: =(Config!$B$11-A8+1)/Config!$B$11 -> 0.998
A9: 5 | B9: =SMALL(Datos!$D$2:$D$1501,A9) -> 145.90844 | C9: =(Config!$B$11-A9+1)/Config!$B$11 -> 0.99733333
A10: 6 | B10: =SMALL(Datos!$D$2:$D$1501,A10) -> 145.93699 | C10: =(Config!$B$11-A10+1)/Config!$B$11 -> 0.99666667
A11: 7 | B11: =SMALL(Datos!$D$2:$D$1501,A11) -> 146.15464 | C11: =(Config!$B$11-A11+1)/Config!$B$11 -> 0.996
A12: 8 | B12: =SMALL(Datos!$D$2:$D$1501,A12) -> 146.29379 | C12: =(Config!$B$11-A12+1)/Config!$B$11 -> 0.99533333
A13: 9 | B13: =SMALL(Datos!$D$2:$D$1501,A13) -> 146.31163 | C13: =(Config!$B$11-A13+1)/Config!$B$11 -> 0.99466667
A14: 10 | B14: =SMALL(Datos!$D$2:$D$1501,A14) -> 146.36872 | C14: =(Config!$B$11-A14+1)/Config!$B$11 -> 0.994
A15: 11 | B15: =SMALL(Datos!$D$2:$D$1501,A15) -> 146.3937 | C15: =(Config!$B$11-A15+1)/Config!$B$11 -> 0.99333333
A16: 12 | B16: =SMALL(Datos!$D$2:$D$1501,A16) -> 146.45435 | C16: =(Config!$B$11-A16+1)/Config!$B$11 -> 0.99266667
... A1504: 1500 | B1504: =SMALL(Datos!$D$2:$D$1501,A1504) -> 177.77473 | C1504: =(Config!$B$11-A1504+1)/Config!$B$11 -> 0.00066666667
